Workbook

Sheet Realised Conversions
A1: New_Id | B1: Status | C1: Followup_owner | D1: Date | E1: Date Clean | F1: Lead Source | G1: FTD | H1: Weightage | I1: Day Status
A2: M148590 | B2: Old Portal_1YT | C2: alina@nexora.live | D2: 46226.743 | E2: =INT(D2) -> 46226 | F2: MAIN WEBSITE (HOT) | G2: =_xlfn.XLOOKUP(A2,FTD!A:A,FTD!C:C) -> 1000 | H2: {=_xlfn.LET( _xlpm.s, TRIM(F2), _xlpm.p, _xlfn.LAMBDA(_xlpm.x, LEFT(_xlpm.s, LEN(_xlpm.x)) = _xlpm.x), _xlfn.IFS( _xlpm.p("meta6"), 1, _xlpm.p("meta"), 3, _xlpm.p("ref"), 3, OR(_xlpm.p("telegram"), _xlpm.p("instagram"), _xlpm.p("stock meme"), _xlpm.p("gx")), 2, OR(_xlpm.p("application"), _xlpm.p("main website"), _xlpm.p("direct (hot)"), _xlpm.p("sunil"), _xlpm.p("prs"), _xlpm.p("invst (hot)")), 1, TRUE, 2 ) )} -> 1 | I2: =_xlfn.XLOOKUP(E2,Calendar!C:C,Calendar!B:B) -> Working Day | M2: Date Clean | N2: Followup_owner | O2: Day Status | P2: Conversions | Q2: Pool
A3: A150877 | B3: Old Portal_1YT | C3: deepa.negi@nexora.live | D3: 46231.493 | E3: =INT(D3) -> 46231 | F3: Referral (HOT) | G3: =_xlfn.XLOOKUP(A3,FTD!A:A,FTD!C:C) -> 2000 | H3: {=_xlfn.LET( _xlpm.s, TRIM(F3), _xlpm.p, _xlfn.LAMBDA(_xlpm.x, LEFT(_xlpm.s, LEN(_xlpm.x)) = _xlpm.x), _xlfn.IFS( _xlpm.p("meta6"), 1, _xlpm.p("meta"), 3, _xlpm.p("ref"), 3, OR(_xlpm.p("telegram"), _xlpm.p("instagram"), _xlpm.p("stock meme"), _xlpm.p("gx")), 2, OR(_xlpm.p("application"), _xlpm.p("main website"), _xlpm.p("direct (hot)"), _xlpm.p("sunil"), _xlpm.p("prs"), _xlpm.p("invst (hot)")), 1, TRUE, 2 ) )} -> 3 | I3: =_xlfn.XLOOKUP(E3,Calendar!C:C,Calendar!B:B) -> Working Day | M3: 46204 | N3: aamir@nexora.live | O3: Working Day | P3: 2 | Q3: =_xlfn.XLOOKUP(N3,Attendance!F:F,Attendance!J:J) -> Dialer | R3: =_xlfn.LET( _xlpm.pool, IFERROR(Q3&"", ""), _xlpm.conv, IFERROR(--P3, 0), _xlpm.mkt, O4="Working Day", IF(_xlpm.pool="1", IF(_xlpm.mkt, IF(_xlpm.conv>=12,700,IF(_xlpm.conv>=8,300,0)), IF(_xlpm.conv>=7,700,IF(_xlpm.conv>=4,300,0))), IF(_xlpm.pool="Meta", IF(_xlpm.mkt, IF(_xlpm.conv>=6,700,IF(_xlpm.conv>=4,400,0)), IF(_xlpm.conv>=4,700,IF(_xlpm.conv>=3,400,0))), IF(_xlpm.mkt, IF(_xlpm.conv>=5,700,IF(_xlpm.conv>=3,500,0)), IF(_xlpm.conv>=3,700,IF(_xlpm.conv>=2,500,0))) ))) -> 0
A4: V140863 | B4: Old Portal_1YT | C4: saurabh.s@nexora.live | D4: 46206.749 | E4: =INT(D4) -> 46206 | F4: MAIN WEBSITE (HOT) | G4: =_xlfn.XLOOKUP(A4,FTD!A:A,FTD!C:C) -> 1500 | H4: {=_xlfn.LET( _xlpm.s, TRIM(F4), _xlpm.p, _xlfn.LAMBDA(_xlpm.x, LEFT(_xlpm.s, LEN(_xlpm.x)) = _xlpm.x), _xlfn.IFS( _xlpm.p("meta6"), 1, _xlpm.p("meta"), 3, _xlpm.p("ref"), 3, OR(_xlpm.p("telegram"), _xlpm.p("instagram"), _xlpm.p("stock meme"), _xlpm.p("gx")), 2, OR(_xlpm.p("application"), _xlpm.p("main website"), _xlpm.p("direct (hot)"), _xlpm.p("sunil"), _xlpm.p("prs"), _xlpm.p("invst (hot)")), 1, TRUE, 2 ) )} -> 1 | I4: =_xlfn.XLOOKUP(E4,Calendar!C:C,Calendar!B:B) -> Working Day | M4: 46204 | N4: anjali@nexora.live | O4: Working Day | P4: 2 | Q4: =_xlfn.XLOOKUP(N4,Attendance!F:F,Attendance!J:J) -> Meta | R4: =_xlfn.LET( _xlpm.pool, IFERROR(Q4&"", ""), _xlpm.conv, IFERROR(--P4, 0), _xlpm.mkt, O5="Working Day", IF(_xlpm.pool="1", IF(_xlpm.mkt, IF(_xlpm.conv>=12,700,IF(_xlpm.conv>=8,300,0)), IF(_xlpm.conv>=7,700,IF(_xlpm.conv>=4,300,0))), IF(_xlpm.pool="Meta", IF(_xlpm.mkt, IF(_xlpm.conv>=6,700,IF(_xlpm.conv>=4,400,0)), IF(_xlpm.conv>=4,700,IF(_xlpm.conv>=3,400,0))), IF(_xlpm.mkt, IF(_xlpm.conv>=5,700,IF(_xlpm.conv>=3,500,0)), IF(_xlpm.conv>=3,700,IF(_xlpm.conv>=2,500,0))) ))) -> 0
A5: S33113 | B5: Not traded new panel | C5: sandeep@nexora.live | D5: 46232.404 | E5: =INT(D5) -> 46232 | F5: META3 | G5: =_xlfn.XLOOKUP(A5,FTD!A:A,FTD!C:C) -> 4000 | H5: {=_xlfn.LET( _xlpm.s, TRIM(F5), _xlpm.p, _xlfn.LAMBDA(_xlpm.x, LEFT(_xlpm.s, LEN(_xlpm.x)) = _xlpm.x), _xlfn.IFS( _xlpm.p("meta6"), 1, _xlpm.p("meta"), 3, _xlpm.p("ref"), 3, OR(_xlpm.p("telegram"), _xlpm.p("instagram"), _xlpm.p("stock meme"), _xlpm.p("gx")), 2, OR(_xlpm.p("application"), _xlpm.p("main website"), _xlpm.p("direct (hot)"), _xlpm.p("sunil"), _xlpm.p("prs"), _xlpm.p("invst (hot)")), 1, TRUE, 2 ) )} -> 3 | I5: =_xlfn.XLOOKUP(E5,Calendar!C:C,Calendar!B:B) -> Working Day | M5: 46204 | N5: ashutosh@nexora.live | O5: Working Day | P5: 4 | Q5: =_xlfn.XLOOKUP(N5,Attendance!F:F,Attendance!J:J) -> 1 | R5: =_xlfn.LET( _xlpm.pool, IFERROR(Q5&"", ""), _xlpm.conv, IFERROR(--P5, 0), _xlpm.mkt, O6="Working Day", IF(_xlpm.pool="1", IF(_xlpm.mkt, IF(_xlpm.conv>=12,700,IF(_xlpm.conv>=8,300,0)), IF(_xlpm.conv>=7,700,IF(_xlpm.conv>=4,300,0))), IF(_xlpm.pool="Meta", IF(_xlpm.mkt, IF(_xlpm.conv>=6,700,IF(_xlpm.conv>=4,400,0)), IF(_xlpm.conv>=4,700,IF(_xlpm.conv>=3,400,0))), IF(_xlpm.mkt, IF(_xlpm.conv>=5,700,IF(_xlpm.conv>=3,500,0)), IF(_xlpm.conv>=3,700,IF(_xlpm.conv>=2,500,0))) ))) -> 0
A6: J145459 | B6: Old Portal_1YT | C6: shambu@nexora.live | D6: 46217.002 | E6: =INT(D6) -> 46217 | F6: MAIN WEBSITE (HOT) | G6: =_xlfn.XLOOKUP(A6,FTD!A:A,FTD!C:C) -> 1000 | H6: {=_xlfn.LET( _xlpm.s, TRIM(F6), _xlpm.p, _xlfn.LAMBDA(_xlpm.x, LEFT(_xlpm.s, LEN(_xlpm.x)) = _xlpm.x), _xlfn.IFS( _xlpm.p("meta6"), 1, _xlpm.p("meta"), 3, _xlpm.p("ref"), 3, OR(_xlpm.p("telegram"), _xlpm.p("instagram"), _xlpm.p("stock meme"), _xlpm.p("gx")), 2, OR(_xlpm.p("application"), _xlpm.p("main website"), _xlpm.p("direct (hot)"), _xlpm.p("sunil"), _xlpm.p("prs"), _xlpm.p("invst (hot)")), 1, TRUE, 2 ) )} -> 1 | I6: =_xlfn.XLOOKUP(E6,Calendar!C:C,Calendar!B:B) -> Working Day | M6: 46204 | N6: chandan.y@nexora.live | O6: Working Day | P6: 1 | Q6: =_xlfn.XLOOKUP(N6,Attendance!F:F,Attendance!J:J) -> #N/A | R6: =_xlfn.LET( _xlpm.pool, IFERROR(Q6&"", ""), _xlpm.conv, IFERROR(--P6, 0), _xlpm.mkt, O7="Working Day", IF(_xlpm.pool="1", IF(_xlpm.mkt, IF(_xlpm.conv>=12,700,IF(_xlpm.conv>=8,300,0)), IF(_xlpm.conv>=7,700,IF(_xlpm.conv>=4,300,0))), IF(_xlpm.pool="Meta", IF(_xlpm.mkt, IF(_xlpm.conv>=6,700,IF(_xlpm.conv>=4,400,0)), IF(_xlpm.conv>=4,700,IF(_xlpm.conv>=3,400,0))), IF(_xlpm.mkt, IF(_xlpm.conv>=5,700,IF(_xlpm.conv>=3,500,0)), IF(_xlpm.conv>=3,700,IF(_xlpm.conv>=2,500,0))) ))) -> 0
A7: B74568 | B7: Not traded new panel | C7: sangita.m@nexora.live | D7: 46212.726 | E7: =INT(D7) -> 46212 | F7: MAIN WEBSITE (HOT) | G7: =_xlfn.XLOOKUP(A7,FTD!A:A,FTD!C:C) -> 1000 | H7: {=_xlfn.LET( _xlpm.s, TRIM(F7), _xlpm.p, _xlfn.LAMBDA(_xlpm.x, LEFT(_xlpm.s, LEN(_xlpm.x)) = _xlpm.x), _xlfn.IFS( _xlpm.p("meta6"), 1, _xlpm.p("meta"), 3, _xlpm.p("ref"), 3, OR(_xlpm.p("telegram"), _xlpm.p("instagram"), _xlpm.p("stock meme"), _xlpm.p("gx")), 2, OR(_xlpm.p("application"), _xlpm.p("main website"), _xlpm.p("direct (hot)"), _xlpm.p("sunil"), _xlpm.p("prs"), _xlpm.p("invst (hot)")), 1, TRUE, 2 ) )} -> 1 | I7: =_xlfn.XLOOKUP(E7,Calendar!C:C,Calendar!B:B) -> Working Day | M7: 46204 | N7: deepa.negi@nexora.live | O7: Working Day | P7: 3 | Q7: =_xlfn.XLOOKUP(N7,Attendance!F:F,Attendance!J:J) -> Meta | R7: =_xlfn.LET( _xlpm.pool, IFERROR(Q7&"", ""), _xlpm.conv, IFERROR(--P7, 0), _xlpm.mkt, O8="Working Day", IF(_xlpm.pool="1", IF(_xlpm.mkt, IF(_xlpm.conv>=12,700,IF(_xlpm.conv>=8,300,0)), IF(_xlpm.conv>=7,700,IF(_xlpm.conv>=4,300,0))), IF(_xlpm.pool="Meta", IF(_xlpm.mkt, IF(_xlpm.conv>=6,700,IF(_xlpm.conv>=4,400,0)), IF(_xlpm.conv>=4,700,IF(_xlpm.conv>=3,400,0))), IF(_xlpm.mkt, IF(_xlpm.conv>=5,700,IF(_xlpm.conv>=3,500,0)), IF(_xlpm.conv>=3,700,IF(_xlpm.conv>=2,500,0))) ))) -> 0
A8: K147126 | B8: Old Portal_1YT | C8: saurabh.s@nexora.live | D8: 46223.426 | E8: =INT(D8) -> 46223 | F8: MAIN WEBSITE (HOT) 1 | G8: =_xlfn.XLOOKUP(A8,FTD!A:A,FTD!C:C) -> 8400 | H8: {=_xlfn.LET( _xlpm.s, TRIM(F8), _xlpm.p, _xlfn.LAMBDA(_xlpm.x, LEFT(_xlpm.s, LEN(_xlpm.x)) = _xlpm.x), _xlfn.IFS( _xlpm.p("meta6"), 1, _xlpm.p("meta"), 3, _xlpm.p("ref"), 3, OR(_xlpm.p("telegram"), _xlpm.p("instagram"), _xlpm.p("stock meme"), _xlpm.p("gx")), 2, OR(_xlpm.p("application"), _xlpm.p("main website"), _xlpm.p("direct (hot)"), _xlpm.p("sunil"), _xlpm.p("prs"), _xlpm.p("invst (hot)")), 1, TRUE, 2 ) )} -> 1 | I8: =_xlfn.XLOOKUP(E8,Calendar!C:C,Calendar!B:B) -> Working Day | M8: 46204 | N8: divya.d@nexora.live | O8: Working Day | P8: 1 | Q8: =_xlfn.XLOOKUP(N8,Attendance!F:F,Attendance!J:J) -> New OJT | R8: =_xlfn.LET( _xlpm.pool, IFERROR(Q8&"", ""), _xlpm.conv, IFERROR(--P8, 0), _xlpm.mkt, O9="Working Day", IF(_xlpm.pool="1", IF(_xlpm.mkt, IF(_xlpm.conv>=12,700,IF(_xlpm.conv>=8,300,0)), IF(_xlpm.conv>=7,700,IF(_xlpm.conv>=4,300,0))), IF(_xlpm.pool="Meta", IF(_xlpm.mkt, IF(_xlpm.conv>=6,700,IF(_xlpm.conv>=4,400,0)), IF(_xlpm.conv>=4,700,IF(_xlpm.conv>=3,400,0))), IF(_xlpm.mkt, IF(_xlpm.conv>=5,700,IF(_xlpm.conv>=3,500,0)), IF(_xlpm.conv>=3,700,IF(_xlpm.conv>=2,500,0))) ))) -> 0
A9: D143267 | B9: Traded_Old Portal | C9: siddhesh@nexora.live | D9: 46216.463 | E9: =INT(D9) -> 46216 | F9: Referral (HOT) | G9: =_xlfn.XLOOKUP(A9,FTD!A:A,FTD!C:C) -> 2000 | H9: {=_xlfn.LET( _xlpm.s, TRIM(F9), _xlpm.p, _xlfn.LAMBDA(_xlpm.x, LEFT(_xlpm.s, LEN(_xlpm.x)) = _xlpm.x), _xlfn.IFS( _xlpm.p("meta6"), 1, _xlpm.p("meta"), 3, _xlpm.p("ref"), 3, OR(_xlpm.p("telegram"), _xlpm.p("instagram"), _xlpm.p("stock meme"), _xlpm.p("gx")), 2, OR(_xlpm.p("application"), _xlpm.p("main website"), _xlpm.p("direct (hot)"), _xlpm.p("sunil"), _xlpm.p("prs"), _xlpm.p("invst (hot)")), 1, TRUE, 2 ) )} -> 3 | I9: =_xlfn.XLOOKUP(E9,Calendar!C:C,Calendar!B:B) -> Working Day | M9: 46204 | N9: fahrukh@nexora.live | O9: Working Day | P9: 1 | Q9: =_xlfn.XLOOKUP(N9,Attendance!F:F,Attendance!J:J) -> Meta | R9: =_xlfn.LET( _xlpm.pool, IFERROR(Q9&"", ""), _xlpm.conv, IFERROR(--P9, 0), _xlpm.mkt, O10="Working Day", IF(_xlpm.pool="1", IF(_xlpm.mkt, IF(_xlpm.conv>=12,700,IF(_xlpm.conv>=8,300,0)), IF(_xlpm.conv>=7,700,IF(_xlpm.conv>=4,300,0))), IF(_xlpm.pool="Meta", IF(_xlpm.mkt, IF(_xlpm.conv>=6,700,IF(_xlpm.conv>=4,400,0)), IF(_xlpm.conv>=4,700,IF(_xlpm.conv>=3,400,0))), IF(_xlpm.mkt, IF(_xlpm.conv>=5,700,IF(_xlpm.conv>=3,500,0)), IF(_xlpm.conv>=3,700,IF(_xlpm.conv>=2,500,0))) ))) -> 0
A10: S149558 | B10: Old Portal_1YT | C10: kanika@nexora.live | D10: 46227.497 | E10: =INT(D10) -> 46227 | F10: Instagram | G10: =_xlfn.XLOOKUP(A10,FTD!A:A,FTD!C:C) -> 500 | H10: {=_xlfn.LET( _xlpm.s, TRIM(F10), _xlpm.p, _xlfn.LAMBDA(_xlpm.x, LEFT(_xlpm.s, LEN(_xlpm.x)) = _xlpm.x), _xlfn.IFS( _xlpm.p("meta6"), 1, _xlpm.p("meta"), 3, _xlpm.p("ref"), 3, OR(_xlpm.p("telegram"), _xlpm.p("instagram"), _xlpm.p("stock meme"), _xlpm.p("gx")), 2, OR(_xlpm.p("application"), _xlpm.p("main website"), _xlpm.p("direct (hot)"), _xlpm.p("sunil"), _xlpm.p("prs"), _xlpm.p("invst (hot)")), 1, TRUE, 2 ) )} -> 2 | I10: =_xlfn.XLOOKUP(E10,Calendar!C:C,Calendar!B:B) -> Working Day | M10: 46204 | N10: haresh@nexora.live | O10: Working Day | P10: 2 | Q10: =_xlfn.XLOOKUP(N10,Attendance!F:F,Attendance!J:J) -> Meta | R10: =_xlfn.LET( _xlpm.pool, IFERROR(Q10&"", ""), _xlpm.conv, IFERROR(--P10, 0), _xlpm.mkt, O11="Working Day", IF(_xlpm.pool="1", IF(_xlpm.mkt, IF(_xlpm.conv>=12,700,IF(_xlpm.conv>=8,300,0)), IF(_xlpm.conv>=7,700,IF(_xlpm.conv>=4,300,0))), IF(_xlpm.pool="Meta", IF(_xlpm.mkt, IF(_xlpm.conv>=6,700,IF(_xlpm.conv>=4,400,0)), IF(_xlpm.conv>=4,700,IF(_xlpm.conv>=3,400,0))), IF(_xlpm.mkt, IF(_xlpm.conv>=5,700,IF(_xlpm.conv>=3,500,0)), IF(_xlpm.conv>=3,700,IF(_xlpm.conv>=2,500,0))) ))) -> 0
A11: A137571 | B11: Traded Conversions | C11: mitali@nexora.live | D11: 46230.398 | E11: =INT(D11) -> 46230 | F11: Meta6 | G11: =_xlfn.XLOOKUP(A11,FTD!A:A,FTD!C:C) -> 1000 | H11: {=_xlfn.LET( _xlpm.s, TRIM(F11), _xlpm.p, _xlfn.LAMBDA(_xlpm.x, LEFT(_xlpm.s, LEN(_xlpm.x)) = _xlpm.x), _xlfn.IFS( _xlpm.p("meta6"), 1, _xlpm.p("meta"), 3, _xlpm.p("ref"), 3, OR(_xlpm.p("telegram"), _xlpm.p("instagram"), _xlpm.p("stock meme"), _xlpm.p("gx")), 2, OR(_xlpm.p("application"), _xlpm.p("main website"), _xlpm.p("direct (hot)"), _xlpm.p("sunil"), _xlpm.p("prs"), _xlpm.p("invst (hot)")), 1, TRUE, 2 ) )} -> 1 | I11: =_xlfn.XLOOKUP(E11,Calendar!C:C,Calendar!B:B) -> Working Day | M11: 46204 | N11: irfan@nexora.live | O11: Working Day | P11: 2 | Q11: =_xlfn.XLOOKUP(N11,Attendance!F:F,Attendance!J:J) -> Meta | R11: =_xlfn.LET( _xlpm.pool, IFERROR(Q11&"", ""), _xlpm.conv, IFERROR(--P11, 0), _xlpm.mkt, O12="Working Day", IF(_xlpm.pool="1", IF(_xlpm.mkt, IF(_xlpm.conv>=12,700,IF(_xlpm.conv>=8,300,0)), IF(_xlpm.conv>=7,700,IF(_xlpm.conv>=4,300,0))), IF(_xlpm.pool="Meta", IF(_xlpm.mkt, IF(_xlpm.conv>=6,700,IF(_xlpm.conv>=4,400,0)), IF(_xlpm.conv>=4,700,IF(_xlpm.conv>=3,400,0))), IF(_xlpm.mkt, IF(_xlpm.conv>=5,700,IF(_xlpm.conv>=3,500,0)), IF(_xlpm.conv>=3,700,IF(_xlpm.conv>=2,500,0))) ))) -> 0
A12: M121811 | B12: Traded Conversions | C12: mitali@nexora.live | D12: 46220.43 | E12: =INT(D12) -> 46220 | F12: MAIN WEBSITE (HOT) | G12: =_xlfn.XLOOKUP(A12,FTD!A:A,FTD!C:C) -> 1000 | H12: {=_xlfn.LET( _xlpm.s, TRIM(F12), _xlpm.p, _xlfn.LAMBDA(_xlpm.x, LEFT(_xlpm.s, LEN(_xlpm.x)) = _xlpm.x), _xlfn.IFS( _xlpm.p("meta6"), 1, _xlpm.p("meta"), 3, _xlpm.p("ref"), 3, OR(_xlpm.p("telegram"), _xlpm.p("instagram"), _xlpm.p("stock meme"), _xlpm.p("gx")), 2, OR(_xlpm.p("application"), _xlpm.p("main website"), _xlpm.p("direct (hot)"), _xlpm.p("sunil"), _xlpm.p("prs"), _xlpm.p("invst (hot)")), 1, TRUE, 2 ) )} -> 1 | I12: =_xlfn.XLOOKUP(E12,Calendar!C:C,Calendar!B:B) -> Working Day | M12: 46204 | N12: kawaljit.k@nexora.live | O12: Working Day | P12: 1 | Q12: =_xlfn.XLOOKUP(N12,Attendance!F:F,Attendance!J:J) -> Meta | R12: =_xlfn.LET( _xlpm.pool, IFERROR(Q12&"", ""), _xlpm.conv, IFERROR(--P12, 0), _xlpm.mkt, O13="Working Day", IF(_xlpm.pool="1", IF(_xlpm.mkt, IF(_xlpm.conv>=12,700,IF(_xlpm.conv>=8,300,0)), IF(_xlpm.conv>=7,700,IF(_xlpm.conv>=4,300,0))), IF(_xlpm.pool="Meta", IF(_xlpm.mkt, IF(_xlpm.conv>=6,700,IF(_xlpm.conv>=4,400,0)), IF(_xlpm.conv>=4,700,IF(_xlpm.conv>=3,400,0))), IF(_xlpm.mkt, IF(_xlpm.conv>=5,700,IF(_xlpm.conv>=3,500,0)), IF(_xlpm.conv>=3,700,IF(_xlpm.conv>=2,500,0))) ))) -> 0
A13: R149379 | B13: Traded Conversions | C13: irfan@nexora.live | D13: 46227.536 | E13: =INT(D13) -> 46227 | F13: META6 | G13: =_xlfn.XLOOKUP(A13,FTD!A:A,FTD!C:C) -> 1001 | H13: {=_xlfn.LET( _xlpm.s, TRIM(F13), _xlpm.p, _xlfn.LAMBDA(_xlpm.x, LEFT(_xlpm.s, LEN(_xlpm.x)) = _xlpm.x), _xlfn.IFS( _xlpm.p("meta6"), 1, _xlpm.p("meta"), 3, _xlpm.p("ref"), 3, OR(_xlpm.p("telegram"), _xlpm.p("instagram"), _xlpm.p("stock meme"), _xlpm.p("gx")), 2, OR(_xlpm.p("application"), _xlpm.p("main website"), _xlpm.p("direct (hot)"), _xlpm.p("sunil"), _xlpm.p("prs"), _xlpm.p("invst (hot)")), 1, TRUE, 2 ) )} -> 1 | I13: =_xlfn.XLOOKUP(E13,Calendar!C:C,Calendar!B:B) -> Working Day | M13: 46204 | N13: nair@nexora.live | O13: Working Day | P13: 2 | Q13: =_xlfn.XLOOKUP(N13,Attendance!F:F,Attendance!J:J) -> 1 | R13: =_xlfn.LET( _xlpm.pool, IFERROR(Q13&"", ""), _xlpm.conv, IFERROR(--P13, 0), _xlpm.mkt, O14="Working Day", IF(_xlpm.pool="1", IF(_xlpm.mkt, IF(_xlpm.conv>=12,700,IF(_xlpm.conv>=8,300,0)), IF(_xlpm.conv>=7,700,IF(_xlpm.conv>=4,300,0))), IF(_xlpm.pool="Meta", IF(_xlpm.mkt, IF(_xlpm.conv>=6,700,IF(_xlpm.conv>=4,400,0)), IF(_xlpm.conv>=4,700,IF(_xlpm.conv>=3,400,0))), IF(_xlpm.mkt, IF(_xlpm.conv>=5,700,IF(_xlpm.conv>=3,500,0)), IF(_xlpm.conv>=3,700,IF(_xlpm.conv>=2,500,0))) ))) -> 0
A14: A134801 | B14: Traded Conversions | C14: ashutosh@nexora.live | D14: 46206.597 | E14: =INT(D14) -> 46206 | F14: MAIN WEBSITE (HOT) | G14: =_xlfn.XLOOKUP(A14,FTD!A:A,FTD!C:C) -> 5000 | H14: {=_xlfn.LET( _xlpm.s, TRIM(F14), _xlpm.p, _xlfn.LAMBDA(_xlpm.x, LEFT(_xlpm.s, LEN(_xlpm.x)) = _xlpm.x), _xlfn.IFS( _xlpm.p("meta6"), 1, _xlpm.p("meta"), 3, _xlpm.p("ref"), 3, OR(_xlpm.p("telegram"), _xlpm.p("instagram"), _xlpm.p("stock meme"), _xlpm.p("gx")), 2, OR(_xlpm.p("application"), _xlpm.p("main website"), _xlpm.p("direct (hot)"), _xlpm.p("sunil"), _xlpm.p("prs"), _xlpm.p("invst (hot)")), 1, TRUE, 2 ) )} -> 1 | I14: =_xlfn.XLOOKUP(E14,Calendar!C:C,Calendar!B:B) -> Working Day | M14: 46204 | N14: oreen@nexora.live | O14: Working Day | P14: 1 | Q14: =_xlfn.XLOOKUP(N14,Attendance!F:F,Attendance!J:J) -> OLD OJT | R14: =_xlfn.LET( _xlpm.pool, IFERROR(Q14&"", ""), _xlpm.conv, IFERROR(--P14, 0), _xlpm.mkt, O15="Working Day", IF(_xlpm.pool="1", IF(_xlpm.mkt, IF(_xlpm.conv>=12,700,IF(_xlpm.conv>=8,300,0)), IF(_xlpm.conv>=7,700,IF(_xlpm.conv>=4,300,0))), IF(_xlpm.pool="Meta", IF(_xlpm.mkt, IF(_xlpm.conv>=6,700,IF(_xlpm.conv>=4,400,0)), IF(_xlpm.conv>=4,700,IF(_xlpm.conv>=3,400,0))), IF(_xlpm.mkt, IF(_xlpm.conv>=5,700,IF(_xlpm.conv>=3,500,0)), IF(_xlpm.conv>=3,700,IF(_xlpm.conv>=2,500,0))) ))) -> 0
... A111: H148363 | B111: Traded Conversions | C111: sachin.g@nexora.live | D111: 46224.435 | E111: =INT(D111) -> 46224 | F111: MAIN WEBSITE (HOT) | G111: =_xlfn.XLOOKUP(A111,FTD!A:A,FTD!C:C) -> 2500 | H111: {=_xlfn.LET( _xlpm.s, TRIM(F111), _xlpm.p, _xlfn.LAMBDA(_xlpm.x, LEFT(_xlpm.s, LEN(_xlpm.x)) = _xlpm.x), _xlfn.IFS( _xlpm.p("meta6"), 1, _xlpm.p("meta"), 3, _xlpm.p("ref"), 3, OR(_xlpm.p("telegram"), _xlpm.p("instagram"), _xlpm.p("stock meme"), _xlpm.p("gx")), 2, OR(_xlpm.p("application"), _xlpm.p("main website"), _xlpm.p("direct (hot)"), _xlpm.p("sunil"), _xlpm.p("prs"), _xlpm.p("invst (hot)")), 1, TRUE, 2 ) )} -> 1 | I111: =_xlfn.XLOOKUP(E111,Calendar!C:C,Calendar!B:B) -> Working Day | M111: 46209 | N111: ashutosh@nexora.live | O111: Working Day | P111: 3 | Q111: =_xlfn.XLOOKUP(N111,Attendance!F:F,Attendance!J:J) -> 1 | R111: =_xlfn.LET( _xlpm.pool, IFERROR(Q111&"", ""), _xlpm.conv, IFERROR(--P111, 0), _xlpm.mkt, O112="Working Day", IF(_xlpm.pool="1", IF(_xlpm.mkt, IF(_xlpm.conv>=12,700,IF(_xlpm.conv>=8,300,0)), IF(_xlpm.conv>=7,700,IF(_xlpm.conv>=4,300,0))), IF(_xlpm.pool="Meta", IF(_xlpm.mkt, IF(_xlpm.conv>=6,700,IF(_xlpm.conv>=4,400,0)), IF(_xlpm.conv>=4,700,IF(_xlpm.conv>=3,400,0))), IF(_xlpm.mkt, IF(_xlpm.conv>=5,700,IF(_xlpm.conv>=3,500,0)), IF(_xlpm.conv>=3,700,IF(_xlpm.conv>=2,500,0))) ))) -> 0
A112: B145911 | B112: Traded Conversions | C112: deepa.negi@nexora.live | D112: 46225.412 | E112: =INT(D112) -> 46225 | G112: =_xlfn.XLOOKUP(A112,FTD!A:A,FTD!C:C) -> 2000 | H112: {=_xlfn.LET( _xlpm.s, TRIM(F112), _xlpm.p, _xlfn.LAMBDA(_xlpm.x, LEFT(_xlpm.s, LEN(_xlpm.x)) = _xlpm.x), _xlfn.IFS( _xlpm.p("meta6"), 1, _xlpm.p("meta"), 3, _xlpm.p("ref"), 3, OR(_xlpm.p("telegram"), _xlpm.p("instagram"), _xlpm.p("stock meme"), _xlpm.p("gx")), 2, OR(_xlpm.p("application"), _xlpm.p("main website"), _xlpm.p("direct (hot)"), _xlpm.p("sunil"), _xlpm.p("prs"), _xlpm.p("invst (hot)")), 1, TRUE, 2 ) )} -> 2 | I112: =_xlfn.XLOOKUP(E112,Calendar!C:C,Calendar!B:B) -> Working Day | M112: 46209 | N112: aslam.k@nexora.live | O112: Working Day | P112: 2 | Q112: =_xlfn.XLOOKUP(N112,Attendance!F:F,Attendance!J:J) -> Dialer | R112: =_xlfn.LET( _xlpm.pool, IFERROR(Q112&"", ""), _xlpm.conv, IFERROR(--P112, 0), _xlpm.mkt, O113="Working Day", IF(_xlpm.pool="1", IF(_xlpm.mkt, IF(_xlpm.conv>=12,700,IF(_xlpm.conv>=8,300,0)), IF(_xlpm.conv>=7,700,IF(_xlpm.conv>=4,300,0))), IF(_xlpm.pool="Meta", IF(_xlpm.mkt, IF(_xlpm.conv>=6,700,IF(_xlpm.conv>=4,400,0)), IF(_xlpm.conv>=4,700,IF(_xlpm.conv>=3,400,0))), IF(_xlpm.mkt, IF(_xlpm.conv>=5,700,IF(_xlpm.conv>=3,500,0)), IF(_xlpm.conv>=3,700,IF(_xlpm.conv>=2,500,0))) ))) -> 0
A113: S143858 | B113: Traded Conversions | C113: prince@nexora.live | D113: 46213.82 | E113: =INT(D113) -> 46213 | F113: Referral (HOT) | G113: =_xlfn.XLOOKUP(A113,FTD!A:A,FTD!C:C) -> 1000 | H113: {=_xlfn.LET( _xlpm.s, TRIM(F113), _xlpm.p, _xlfn.LAMBDA(_xlpm.x, LEFT(_xlpm.s, LEN(_xlpm.x)) = _xlpm.x), _xlfn.IFS( _xlpm.p("meta6"), 1, _xlpm.p("meta"), 3, _xlpm.p("ref"), 3, OR(_xlpm.p("telegram"), _xlpm.p("instagram"), _xlpm.p("stock meme"), _xlpm.p("gx")), 2, OR(_xlpm.p("application"), _xlpm.p("main website"), _xlpm.p("direct (hot)"), _xlpm.p("sunil"), _xlpm.p("prs"), _xlpm.p("invst (hot)")), 1, TRUE, 2 ) )} -> 3 | I113: =_xlfn.XLOOKUP(E113,Calendar!C:C,Calendar!B:B) -> Working Day | M113: 46209 | N113: deepa.negi@nexora.live | O113: Working Day | P113: 1 | Q113: =_xlfn.XLOOKUP(N113,Attendance!F:F,Attendance!J:J) -> Meta | R113: =_xlfn.LET( _xlpm.pool, IFERROR(Q113&"", ""), _xlpm.conv, IFERROR(--P113, 0), _xlpm.mkt, O114="Working Day", IF(_xlpm.pool="1", IF(_xlpm.mkt, IF(_xlpm.conv>=12,700,IF(_xlpm.conv>=8,300,0)), IF(_xlpm.conv>=7,700,IF(_xlpm.conv>=4,300,0))), IF(_xlpm.pool="Meta", IF(_xlpm.mkt, IF(_xlpm.conv>=6,700,IF(_xlpm.conv>=4,400,0)), IF(_xlpm.conv>=4,700,IF(_xlpm.conv>=3,400,0))), IF(_xlpm.mkt, IF(_xlpm.conv>=5,700,IF(_xlpm.conv>=3,500,0)), IF(_xlpm.conv>=3,700,IF(_xlpm.conv>=2,500,0))) ))) -> 0
A114: S148976 | B114: Traded Conversions | C114: sachin.g@nexora.live | D114: 46226.409 | E114: =INT(D114) -> 46226 | F114: MAIN WEBSITE (HOT) | G114: =_xlfn.XLOOKUP(A114,FTD!A:A,FTD!C:C) -> 40000 | H114: {=_xlfn.LET( _xlpm.s, TRIM(F114), _xlpm.p, _xlfn.LAMBDA(_xlpm.x, LEFT(_xlpm.s, LEN(_xlpm.x)) = _xlpm.x), _xlfn.IFS( _xlpm.p("meta6"), 1, _xlpm.p("meta"), 3, _xlpm.p("ref"), 3, OR(_xlpm.p("telegram"), _xlpm.p("instagram"), _xlpm.p("stock meme"), _xlpm.p("gx")), 2, OR(_xlpm.p("application"), _xlpm.p("main website"), _xlpm.p("direct (hot)"), _xlpm.p("sunil"), _xlpm.p("prs"), _xlpm.p("invst (hot)")), 1, TRUE, 2 ) )} -> 1 | I114: =_xlfn.XLOOKUP(E114,Calendar!C:C,Calendar!B:B) -> Working Day | M114: 46209 | N114: divya.d@nexora.live | O114: Working Day | P114: 1 | Q114: =_xlfn.XLOOKUP(N114,Attendance!F:F,Attendance!J:J) -> New OJT | R114: =_xlfn.LET( _xlpm.pool, IFERROR(Q114&"", ""), _xlpm.conv, IFERROR(--P114, 0), _xlpm.mkt, O115="Working Day", IF(_xlpm.pool="1", IF(_xlpm.mkt, IF(_xlpm.conv>=12,700,IF(_xlpm.conv>=8,300,0)), IF(_xlpm.conv>=7,700,IF(_xlpm.conv>=4,300,0))), IF(_xlpm.pool="Meta", IF(_xlpm.mkt, IF(_xlpm.conv>=6,700,IF(_xlpm.conv>=4,400,0)), IF(_xlpm.conv>=4,700,IF(_xlpm.conv>=3,400,0))), IF(_xlpm.mkt, IF(_xlpm.conv>=5,700,IF(_xlpm.conv>=3,500,0)), IF(_xlpm.conv>=3,700,IF(_xlpm.conv>=2,500,0))) ))) -> 0
A115: N139608 | B115: Old Portal_1YT | C115: haresh@nexora.live | D115: 46209.389 | E115: =INT(D115) -> 46209 | F115: MAIN WEBSITE (HOT) | G115: =_xlfn.XLOOKUP(A115,FTD!A:A,FTD!C:C) -> 1000 | H115: {=_xlfn.LET( _xlpm.s, TRIM(F115), _xlpm.p, _xlfn.LAMBDA(_xlpm.x, LEFT(_xlpm.s, LEN(_xlpm.x)) = _xlpm.x), _xlfn.IFS( _xlpm.p("meta6"), 1, _xlpm.p("meta"), 3, _xlpm.p("ref"), 3, OR(_xlpm.p("telegram"), _xlpm.p("instagram"), _xlpm.p("stock meme"), _xlpm.p("gx")), 2, OR(_xlpm.p("application"), _xlpm.p("main website"), _xlpm.p("direct (hot)"), _xlpm.p("sunil"), _xlpm.p("prs"), _xlpm.p("invst (hot)")), 1, TRUE, 2 ) )} -> 1 | I115: =_xlfn.XLOOKUP(E115,Calendar!C:C,Calendar!B:B) -> Working Day | M115: 46209 | N115: fahrukh@nexora.live | O115: Working Day | P115: 1 | Q115: =_xlfn.XLOOKUP(N115,Attendance!F:F,Attendance!J:J) -> Meta | R115: =_xlfn.LET( _xlpm.pool, IFERROR(Q115&"", ""), _xlpm.conv, IFERROR(--P115, 0), _xlpm.mkt, O116="Working Day", IF(_xlpm.pool="1", IF(_xlpm.mkt, IF(_xlpm.conv>=12,700,IF(_xlpm.conv>=8,300,0)), IF(_xlpm.conv>=7,700,IF(_xlpm.conv>=4,300,0))), IF(_xlpm.pool="Meta", IF(_xlpm.mkt, IF(_xlpm.conv>=6,700,IF(_xlpm.conv>=4,400,0)), IF(_xlpm.conv>=4,700,IF(_xlpm.conv>=3,400,0))), IF(_xlpm.mkt, IF(_xlpm.conv>=5,700,IF(_xlpm.conv>=3,500,0)), IF(_xlpm.conv>=3,700,IF(_xlpm.conv>=2,500,0))) ))) -> 0
A116: S150201 | B116: Old Portal_1YT | C116: haresh@nexora.live | D116: 46232.862 | E116: =INT(D116) -> 46232 | F116: MAIN WEBSITE (HOT) 1 | G116: =_xlfn.XLOOKUP(A116,FTD!A:A,FTD!C:C) -> 10000 | H116: {=_xlfn.LET( _xlpm.s, TRIM(F116), _xlpm.p, _xlfn.LAMBDA(_xlpm.x, LEFT(_xlpm.s, LEN(_xlpm.x)) = _xlpm.x), _xlfn.IFS( _xlpm.p("meta6"), 1, _xlpm.p("meta"), 3, _xlpm.p("ref"), 3, OR(_xlpm.p("telegram"), _xlpm.p("instagram"), _xlpm.p("stock meme"), _xlpm.p("gx")), 2, OR(_xlpm.p("application"), _xlpm.p("main website"), _xlpm.p("direct (hot)"), _xlpm.p("sunil"), _xlpm.p("prs"), _xlpm.p("invst (hot)")), 1, TRUE, 2 ) )} -> 1 | I116: =_xlfn.XLOOKUP(E116,Calendar!C:C,Calendar!B:B) -> Working Day | M116: 46209 | N116: haresh@nexora.live | O116: Working Day | P116: 2 | Q116: =_xlfn.XLOOKUP(N116,Attendance!F:F,Attendance!J:J) -> Meta | R116: =_xlfn.LET( _xlpm.pool, IFERROR(Q116&"", ""), _xlpm.conv, IFERROR(--P116, 0), _xlpm.mkt, O117="Working Day", IF(_xlpm.pool="1", IF(_xlpm.mkt, IF(_xlpm.conv>=12,700,IF(_xlpm.conv>=8,300,0)), IF(_xlpm.conv>=7,700,IF(_xlpm.conv>=4,300,0))), IF(_xlpm.pool="Meta", IF(_xlpm.mkt, IF(_xlpm.conv>=6,700,IF(_xlpm.conv>=4,400,0)), IF(_xlpm.conv>=4,700,IF(_xlpm.conv>=3,400,0))), IF(_xlpm.mkt, IF(_xlpm.conv>=5,700,IF(_xlpm.conv>=3,500,0)), IF(_xlpm.conv>=3,700,IF(_xlpm.conv>=2,500,0))) ))) -> 0
A117: P145664 | B117: Old Portal_1YT | C117: shambu@nexora.live | D117: 46217.487 | E117: =INT(D117) -> 46217 | F117: MAIN WEBSITE (HOT) | G117: =_xlfn.XLOOKUP(A117,FTD!A:A,FTD!C:C) -> 1000 | H117: {=_xlfn.LET( _xlpm.s, TRIM(F117), _xlpm.p, _xlfn.LAMBDA(_xlpm.x, LEFT(_xlpm.s, LEN(_xlpm.x)) = _xlpm.x), _xlfn.IFS( _xlpm.p("meta6"), 1, _xlpm.p("meta"), 3, _xlpm.p("ref"), 3, OR(_xlpm.p("telegram"), _xlpm.p("instagram"), _xlpm.p("stock meme"), _xlpm.p("gx")), 2, OR(_xlpm.p("application"), _xlpm.p("main website"), _xlpm.p("direct (hot)"), _xlpm.p("sunil"), _xlpm.p("prs"), _xlpm.p("invst (hot)")), 1, TRUE, 2 ) )} -> 1 | I117: =_xlfn.XLOOKUP(E117,Calendar!C:C,Calendar!B:B) -> Working Day | M117: 46209 | N117: irfan@nexora.live | O117: Working Day | P117: 2 | Q117: =_xlfn.XLOOKUP(N117,Attendance!F:F,Attendance!J:J) -> Meta | R117: =_xlfn.LET( _xlpm.pool, IFERROR(Q117&"", ""), _xlpm.conv, IFERROR(--P117, 0), _xlpm.mkt, O118="Working Day", IF(_xlpm.pool="1", IF(_xlpm.mkt, IF(_xlpm.conv>=12,700,IF(_xlpm.conv>=8,300,0)), IF(_xlpm.conv>=7,700,IF(_xlpm.conv>=4,300,0))), IF(_xlpm.pool="Meta", IF(_xlpm.mkt, IF(_xlpm.conv>=6,700,IF(_xlpm.conv>=4,400,0)), IF(_xlpm.conv>=4,700,IF(_xlpm.conv>=3,400,0))), IF(_xlpm.mkt, IF(_xlpm.conv>=5,700,IF(_xlpm.conv>=3,500,0)), IF(_xlpm.conv>=3,700,IF(_xlpm.conv>=2,500,0))) ))) -> 0
A118: A146729 | B118: Old Portal_1YT | C118: haresh@nexora.live | D118: 46231.412 | E118: =INT(D118) -> 46231 | F118: MAIN WEBSITE (HOT) | G118: =_xlfn.XLOOKUP(A118,FTD!A:A,FTD!C:C) -> 126 | H118: {=_xlfn.LET( _xlpm.s, TRIM(F118), _xlpm.p, _xlfn.LAMBDA(_xlpm.x, LEFT(_xlpm.s, LEN(_xlpm.x)) = _xlpm.x), _xlfn.IFS( _xlpm.p("meta6"), 1, _xlpm.p("meta"), 3, _xlpm.p("ref"), 3, OR(_xlpm.p("telegram"), _xlpm.p("instagram"), _xlpm.p("stock meme"), _xlpm.p("gx")), 2, OR(_xlpm.p("application"), _xlpm.p("main website"), _xlpm.p("direct (hot)"), _xlpm.p("sunil"), _xlpm.p("prs"), _xlpm.p("invst (hot)")), 1, TRUE, 2 ) )} -> 1 | I118: =_xlfn.XLOOKUP(E118,Calendar!C:C,Calendar!B:B) -> Working Day | M118: 46209 | N118: ishika@nexora.live | O118: Working Day | P118: 2 | Q118: =_xlfn.XLOOKUP(N118,Attendance!F:F,Attendance!J:J) -> OJT 2 | R118: =_xlfn.LET( _xlpm.pool, IFERROR(Q118&"", ""), _xlpm.conv, IFERROR(--P118, 0), _xlpm.mkt, O119="Working Day", IF(_xlpm.pool="1", IF(_xlpm.mkt, IF(_xlpm.conv>=12,700,IF(_xlpm.conv>=8,300,0)), IF(_xlpm.conv>=7,700,IF(_xlpm.conv>=4,300,0))), IF(_xlpm.pool="Meta", IF(_xlpm.mkt, IF(_xlpm.conv>=6,700,IF(_xlpm.conv>=4,400,0)), IF(_xlpm.conv>=4,700,IF(_xlpm.conv>=3,400,0))), IF(_xlpm.mkt, IF(_xlpm.conv>=5,700,IF(_xlpm.conv>=3,500,0)), IF(_xlpm.conv>=3,700,IF(_xlpm.conv>=2,500,0))) ))) -> 0
A119: S144375 | B119: Old Portal_1YT | C119: sushil@nexora.live | D119: 46215.205 | E119: =INT(D119) -> 46215 | F119: Meta-T | G119: =_xlfn.XLOOKUP(A119,FTD!A:A,FTD!C:C) -> 2000 | H119: {=_xlfn.LET( _xlpm.s, TRIM(F119), _xlpm.p, _xlfn.LAMBDA(_xlpm.x, LEFT(_xlpm.s, LEN(_xlpm.x)) = _xlpm.x), _xlfn.IFS( _xlpm.p("meta6"), 1, _xlpm.p("meta"), 3, _xlpm.p("ref"), 3, OR(_xlpm.p("telegram"), _xlpm.p("instagram"), _xlpm.p("stock meme"), _xlpm.p("gx")), 2, OR(_xlpm.p("application"), _xlpm.p("main website"), _xlpm.p("direct (hot)"), _xlpm.p("sunil"), _xlpm.p("prs"), _xlpm.p("invst (hot)")), 1, TRUE, 2 ) )} -> 3 | I119: =_xlfn.XLOOKUP(E119,Calendar!C:C,Calendar!B:B) -> Sunday | M119: 46209 | N119: kanika@nexora.live | O119: Working Day | P119: 1 | Q119: =_xlfn.XLOOKUP(N119,Attendance!F:F,Attendance!J:J) -> OJT 1 | R119: =_xlfn.LET( _xlpm.pool, IFERROR(Q119&"", ""), _xlpm.conv, IFERROR(--P119, 0), _xlpm.mkt, O120="Working Day", IF(_xlpm.pool="1", IF(_xlpm.mkt, IF(_xlpm.conv>=12,700,IF(_xlpm.conv>=8,300,0)), IF(_xlpm.conv>=7,700,IF(_xlpm.conv>=4,300,0))), IF(_xlpm.pool="Meta", IF(_xlpm.mkt, IF(_xlpm.conv>=6,700,IF(_xlpm.conv>=4,400,0)), IF(_xlpm.conv>=4,700,IF(_xlpm.conv>=3,400,0))), IF(_xlpm.mkt, IF(_xlpm.conv>=5,700,IF(_xlpm.conv>=3,500,0)), IF(_xlpm.conv>=3,700,IF(_xlpm.conv>=2,500,0))) ))) -> 0
A120: R142106 | B120: Traded_Old Portal | C120: deepa.negi@nexora.live | D120: 46230.457 | E120: =INT(D120) -> 46230 | F120: MAIN WEBSITE (HOT) | G120: =_xlfn.XLOOKUP(A120,FTD!A:A,FTD!C:C) -> 10000 | H120: {=_xlfn.LET( _xlpm.s, TRIM(F120), _xlpm.p, _xlfn.LAMBDA(_xlpm.x, LEFT(_xlpm.s, LEN(_xlpm.x)) = _xlpm.x), _xlfn.IFS( _xlpm.p("meta6"), 1, _xlpm.p("meta"), 3, _xlpm.p("ref"), 3, OR(_xlpm.p("telegram"), _xlpm.p("instagram"), _xlpm.p("stock meme"), _xlpm.p("gx")), 2, OR(_xlpm.p("application"), _xlpm.p("main website"), _xlpm.p("direct (hot)"), _xlpm.p("sunil"), _xlpm.p("prs"), _xlpm.p("invst (hot)")), 1, TRUE, 2 ) )} -> 1 | I120: =_xlfn.XLOOKUP(E120,Calendar!C:C,Calendar!B:B) -> Working Day | M120: 46209 | N120: kawaljit.k@nexora.live | O120: Working Day | P120: 1 | Q120: =_xlfn.XLOOKUP(N120,Attendance!F:F,Attendance!J:J) -> Meta | R120: =_xlfn.LET( _xlpm.pool, IFERROR(Q120&"", ""), _xlpm.conv, IFERROR(--P120, 0), _xlpm.mkt, O121="Working Day", IF(_xlpm.pool="1", IF(_xlpm.mkt, IF(_xlpm.conv>=12,700,IF(_xlpm.conv>=8,300,0)), IF(_xlpm.conv>=7,700,IF(_xlpm.conv>=4,300,0))), IF(_xlpm.pool="Meta", IF(_xlpm.mkt, IF(_xlpm.conv>=6,700,IF(_xlpm.conv>=4,400,0)), IF(_xlpm.conv>=4,700,IF(_xlpm.conv>=3,400,0))), IF(_xlpm.mkt, IF(_xlpm.conv>=5,700,IF(_xlpm.conv>=3,500,0)), IF(_xlpm.conv>=3,700,IF(_xlpm.conv>=2,500,0))) ))) -> 0
A121: S146794 | B121: Old Portal_1YT | C121: deepraj@nexora.live | D121: 46220.774 | E121: =INT(D121) -> 46220 | F121: MAIN WEBSITE (HOT) | G121: =_xlfn.XLOOKUP(A121,FTD!A:A,FTD!C:C) -> 1205 | H121: {=_xlfn.LET( _xlpm.s, TRIM(F121), _xlpm.p, _xlfn.LAMBDA(_xlpm.x, LEFT(_xlpm.s, LEN(_xlpm.x)) = _xlpm.x), _xlfn.IFS( _xlpm.p("meta6"), 1, _xlpm.p("meta"), 3, _xlpm.p("ref"), 3, OR(_xlpm.p("telegram"), _xlpm.p("instagram"), _xlpm.p("stock meme"), _xlpm.p("gx")), 2, OR(_xlpm.p("application"), _xlpm.p("main website"), _xlpm.p("direct (hot)"), _xlpm.p("sunil"), _xlpm.p("prs"), _xlpm.p("invst (hot)")), 1, TRUE, 2 ) )} -> 1 | I121: =_xlfn.XLOOKUP(E121,Calendar!C:C,Calendar!B:B) -> Working Day | M121: 46209 | N121: mitali@nexora.live | O121: Working Day | P121: 1 | Q121: =_xlfn.XLOOKUP(N121,Attendance!F:F,Attendance!J:J) -> Telegram | R121: =_xlfn.LET( _xlpm.pool, IFERROR(Q121&"", ""), _xlpm.conv, IFERROR(--P121, 0), _xlpm.mkt, O122="Working Day", IF(_xlpm.pool="1", IF(_xlpm.mkt, IF(_xlpm.conv>=12,700,IF(_xlpm.conv>=8,300,0)), IF(_xlpm.conv>=7,700,IF(_xlpm.conv>=4,300,0))), IF(_xlpm.pool="Meta", IF(_xlpm.mkt, IF(_xlpm.conv>=6,700,IF(_xlpm.conv>=4,400,0)), IF(_xlpm.conv>=4,700,IF(_xlpm.conv>=3,400,0))), IF(_xlpm.mkt, IF(_xlpm.conv>=5,700,IF(_xlpm.conv>=3,500,0)), IF(_xlpm.conv>=3,700,IF(_xlpm.conv>=2,500,0))) ))) -> 0
A122: K151454 | B122: Old Portal_1YT | C122: oreen@nexora.live | D122: 46231.866 | E122: =INT(D122) -> 46231 | F122: MAIN WEBSITE (HOT) 1 | G122: =_xlfn.XLOOKUP(A122,FTD!A:A,FTD!C:C) -> 3000 | H122: {=_xlfn.LET( _xlpm.s, TRIM(F122), _xlpm.p, _xlfn.LAMBDA(_xlpm.x, LEFT(_xlpm.s, LEN(_xlpm.x)) = _xlpm.x), _xlfn.IFS( _xlpm.p("meta6"), 1, _xlpm.p("meta"), 3, _xlpm.p("ref"), 3, OR(_xlpm.p("telegram"), _xlpm.p("instagram"), _xlpm.p("stock meme"), _xlpm.p("gx")), 2, OR(_xlpm.p("application"), _xlpm.p("main website"), _xlpm.p("direct (hot)"), _xlpm.p("sunil"), _xlpm.p("prs"), _xlpm.p("invst (hot)")), 1, TRUE, 2 ) )} -> 1 | I122: =_xlfn.XLOOKUP(E122,Calendar!C:C,Calendar!B:B) -> Working Day | M122: 46209 | N122: nair@nexora.live | O122: Working Day | P122: 6 | Q122: =_xlfn.XLOOKUP(N122,Attendance!F:F,Attendance!J:J) -> 1 | R122: =_xlfn.LET( _xlpm.pool, IFERROR(Q122&"", ""), _xlpm.conv, IFERROR(--P122, 0), _xlpm.mkt, O123="Working Day", IF(_xlpm.pool="1", IF(_xlpm.mkt, IF(_xlpm.conv>=12,700,IF(_xlpm.conv>=8,300,0)), IF(_xlpm.conv>=7,700,IF(_xlpm.conv>=4,300,0))), IF(_xlpm.pool="Meta", IF(_xlpm.mkt, IF(_xlpm.conv>=6,700,IF(_xlpm.conv>=4,400,0)), IF(_xlpm.conv>=4,700,IF(_xlpm.conv>=3,400,0))), IF(_xlpm.mkt, IF(_xlpm.conv>=5,700,IF(_xlpm.conv>=3,500,0)), IF(_xlpm.conv>=3,700,IF(_xlpm.conv>=2,500,0))) ))) -> 0
A123: I133072 | B123: Old Portal_1YT | C123: chandan.y@nexora.live | D123: 46226.553 | E123: =INT(D123) -> 46226 | F123: MAIN WEBSITE (HOT) 1 | G123: =_xlfn.XLOOKUP(A123,FTD!A:A,FTD!C:C) -> 1000 | H123: {=_xlfn.LET( _xlpm.s, TRIM(F123), _xlpm.p, _xlfn.LAMBDA(_xlpm.x, LEFT(_xlpm.s, LEN(_xlpm.x)) = _xlpm.x), _xlfn.IFS( _xlpm.p("meta6"), 1, _xlpm.p("meta"), 3, _xlpm.p("ref"), 3, OR(_xlpm.p("telegram"), _xlpm.p("instagram"), _xlpm.p("stock meme"), _xlpm.p("gx")), 2, OR(_xlpm.p("application"), _xlpm.p("main website"), _xlpm.p("direct (hot)"), _xlpm.p("sunil"), _xlpm.p("prs"), _xlpm.p("invst (hot)")), 1, TRUE, 2 ) )} -> 1 | I123: =_xlfn.XLOOKUP(E123,Calendar!C:C,Calendar!B:B) -> Working Day | M123: 46209 | N123: prince@nexora.live | O123: Working Day | P123: 3 | Q123: =_xlfn.XLOOKUP(N123,Attendance!F:F,Attendance!J:J) -> 1 | R123: =_xlfn.LET( _xlpm.pool, IFERROR(Q123&"", ""), _xlpm.conv, IFERROR(--P123, 0), _xlpm.mkt, O124="Working Day", IF(_xlpm.pool="1", IF(_xlpm.mkt, IF(_xlpm.conv>=12,700,IF(_xlpm.conv>=8,300,0)), IF(_xlpm.conv>=7,700,IF(_xlpm.conv>=4,300,0))), IF(_xlpm.pool="Meta", IF(_xlpm.mkt, IF(_xlpm.conv>=6,700,IF(_xlpm.conv>=4,400,0)), IF(_xlpm.conv>=4,700,IF(_xlpm.conv>=3,400,0))), IF(_xlpm.mkt, IF(_xlpm.conv>=5,700,IF(_xlpm.conv>=3,500,0)), IF(_xlpm.conv>=3,700,IF(_xlpm.conv>=2,500,0))) ))) -> 0
A124: G136192 | B124: Old Portal_1YT | C124: ishika@nexora.live | D124: 46219.825 | E124: =INT(D124) -> 46219 | F124: META3 | G124: =_xlfn.XLOOKUP(A124,FTD!A:A,FTD!C:C) -> 1000 | H124: {=_xlfn.LET( _xlpm.s, TRIM(F124), _xlpm.p, _xlfn.LAMBDA(_xlpm.x, LEFT(_xlpm.s, LEN(_xlpm.x)) = _xlpm.x), _xlfn.IFS( _xlpm.p("meta6"), 1, _xlpm.p("meta"), 3, _xlpm.p("ref"), 3, OR(_xlpm.p("telegram"), _xlpm.p("instagram"), _xlpm.p("stock meme"), _xlpm.p("gx")), 2, OR(_xlpm.p("application"), _xlpm.p("main website"), _xlpm.p("direct (hot)"), _xlpm.p("sunil"), _xlpm.p("prs"), _xlpm.p("invst (hot)")), 1, TRUE, 2 ) )} -> 3 | I124: =_xlfn.XLOOKUP(E124,Calendar!C:C,Calendar!B:B) -> Working Day | M124: 46209 | N124: ramya@nexora.live | O124: Working Day | P124: 1 | Q124: =_xlfn.XLOOKUP(N124,Attendance!F:F,Attendance!J:J) -> OJT 2 | R124: =_xlfn.LET( _xlpm.pool, IFERROR(Q124&"", ""), _xlpm.conv, IFERROR(--P124, 0), _xlpm.mkt, O125="Working Day", IF(_xlpm.pool="1", IF(_xlpm.mkt, IF(_xlpm.conv>=12,700,IF(_xlpm.conv>=8,300,0)), IF(_xlpm.conv>=7,700,IF(_xlpm.conv>=4,300,0))), IF(_xlpm.pool="Meta", IF(_xlpm.mkt, IF(_xlpm.conv>=6,700,IF(_xlpm.conv>=4,400,0)), IF(_xlpm.conv>=4,700,IF(_xlpm.conv>=3,400,0))), IF(_xlpm.mkt, IF(_xlpm.conv>=5,700,IF(_xlpm.conv>=3,500,0)), IF(_xlpm.conv>=3,700,IF(_xlpm.conv>=2,500,0))) ))) -> 0
... A283: B146079 | B283: Traded Conversions | C283: sachin.g@nexora.live | D283: 46218.542 | E283: =INT(D283) -> 46218 | F283: MAIN WEBSITE (HOT) | G283: =_xlfn.XLOOKUP(A283,FTD!A:A,FTD!C:C) -> 10000 | H283: {=_xlfn.LET( _xlpm.s, TRIM(F283), _xlpm.p, _xlfn.LAMBDA(_xlpm.x, LEFT(_xlpm.s, LEN(_xlpm.x)) = _xlpm.x), _xlfn.IFS( _xlpm.p("meta6"), 1, _xlpm.p("meta"), 3, _xlpm.p("ref"), 3, OR(_xlpm.p("telegram"), _xlpm.p("instagram"), _xlpm.p("stock meme"), _xlpm.p("gx")), 2, OR(_xlpm.p("application"), _xlpm.p("main website"), _xlpm.p("direct (hot)"), _xlpm.p("sunil"), _xlpm.p("prs"), _xlpm.p("invst (hot)")), 1, TRUE, 2 ) )} -> 1 | I283: =_xlfn.XLOOKUP(E283,Calendar!C:C,Calendar!B:B) -> Working Day | M283: 46217 | N283: anjali@nexora.live | O283: Working Day | P283: 2 | Q283: =_xlfn.XLOOKUP(N283,Attendance!F:F,Attendance!J:J) -> Meta | R283: =_xlfn.LET( _xlpm.pool, IFERROR(Q283&"", ""), _xlpm.conv, IFERROR(--P283, 0), _xlpm.mkt, O284="Working Day", IF(_xlpm.pool="1", IF(_xlpm.mkt, IF(_xlpm.conv>=12,700,IF(_xlpm.conv>=8,300,0)), IF(_xlpm.conv>=7,700,IF(_xlpm.conv>=4,300,0))), IF(_xlpm.pool="Meta", IF(_xlpm.mkt, IF(_xlpm.conv>=6,700,IF(_xlpm.conv>=4,400,0)), IF(_xlpm.conv>=4,700,IF(_xlpm.conv>=3,400,0))), IF(_xlpm.mkt, IF(_xlpm.conv>=5,700,IF(_xlpm.conv>=3,500,0)), IF(_xlpm.conv>=3,700,IF(_xlpm.conv>=2,500,0))) ))) -> 0
A284: R143955 | B284: Traded Conversions | C284: deepa.negi@nexora.live | D284: 46218.511 | E284: =INT(D284) -> 46218 | G284: =_xlfn.XLOOKUP(A284,FTD!A:A,FTD!C:C) -> 1000 | H284: {=_xlfn.LET( _xlpm.s, TRIM(F284), _xlpm.p, _xlfn.LAMBDA(_xlpm.x, LEFT(_xlpm.s, LEN(_xlpm.x)) = _xlpm.x), _xlfn.IFS( _xlpm.p("meta6"), 1, _xlpm.p("meta"), 3, _xlpm.p("ref"), 3, OR(_xlpm.p("telegram"), _xlpm.p("instagram"), _xlpm.p("stock meme"), _xlpm.p("gx")), 2, OR(_xlpm.p("application"), _xlpm.p("main website"), _xlpm.p("direct (hot)"), _xlpm.p("sunil"), _xlpm.p("prs"), _xlpm.p("invst (hot)")), 1, TRUE, 2 ) )} -> 2 | I284: =_xlfn.XLOOKUP(E284,Calendar!C:C,Calendar!B:B) -> Working Day | M284: 46217 | N284: ashutosh@nexora.live | O284: Working Day | P284: 3 | Q284: =_xlfn.XLOOKUP(N284,Attendance!F:F,Attendance!J:J) -> 1 | R284: =_xlfn.LET( _xlpm.pool, IFERROR(Q284&"", ""), _xlpm.conv, IFERROR(--P284, 0), _xlpm.mkt, O285="Working Day", IF(_xlpm.pool="1", IF(_xlpm.mkt, IF(_xlpm.conv>=12,700,IF(_xlpm.conv>=8,300,0)), IF(_xlpm.conv>=7,700,IF(_xlpm.conv>=4,300,0))), IF(_xlpm.pool="Meta", IF(_xlpm.mkt, IF(_xlpm.conv>=6,700,IF(_xlpm.conv>=4,400,0)), IF(_xlpm.conv>=4,700,IF(_xlpm.conv>=3,400,0))), IF(_xlpm.mkt, IF(_xlpm.conv>=5,700,IF(_xlpm.conv>=3,500,0)), IF(_xlpm.conv>=3,700,IF(_xlpm.conv>=2,500,0))) ))) -> 0
A285: M146482 | B285: Traded Conversions | C285: sachin.g@nexora.live | D285: 46219.482 | E285: =INT(D285) -> 46219 | F285: MAIN WEBSITE (HOT) | G285: =_xlfn.XLOOKUP(A285,FTD!A:A,FTD!C:C) -> 10000 | H285: {=_xlfn.LET( _xlpm.s, TRIM(F285), _xlpm.p, _xlfn.LAMBDA(_xlpm.x, LEFT(_xlpm.s, LEN(_xlpm.x)) = _xlpm.x), _xlfn.IFS( _xlpm.p("meta6"), 1, _xlpm.p("meta"), 3, _xlpm.p("ref"), 3, OR(_xlpm.p("telegram"), _xlpm.p("instagram"), _xlpm.p("stock meme"), _xlpm.p("gx")), 2, OR(_xlpm.p("application"), _xlpm.p("main website"), _xlpm.p("direct (hot)"), _xlpm.p("sunil"), _xlpm.p("prs"), _xlpm.p("invst (hot)")), 1, TRUE, 2 ) )} -> 1 | I285: =_xlfn.XLOOKUP(E285,Calendar!C:C,Calendar!B:B) -> Working Day | M285: 46217 | N285: chandan.y@nexora.live | O285: Working Day | P285: 2 | Q285: =_xlfn.XLOOKUP(N285,Attendance!F:F,Attendance!J:J) -> #N/A | R285: =_xlfn.LET( _xlpm.pool, IFERROR(Q285&"", ""), _xlpm.conv, IFERROR(--P285, 0), _xlpm.mkt, O286="Working Day", IF(_xlpm.pool="1", IF(_xlpm.mkt, IF(_xlpm.conv>=12,700,IF(_xlpm.conv>=8,300,0)), IF(_xlpm.conv>=7,700,IF(_xlpm.conv>=4,300,0))), IF(_xlpm.pool="Meta", IF(_xlpm.mkt, IF(_xlpm.conv>=6,700,IF(_xlpm.conv>=4,400,0)), IF(_xlpm.conv>=4,700,IF(_xlpm.conv>=3,400,0))), IF(_xlpm.mkt, IF(_xlpm.conv>=5,700,IF(_xlpm.conv>=3,500,0)), IF(_xlpm.conv>=3,700,IF(_xlpm.conv>=2,500,0))) ))) -> 0
A286: H149114 | B286: Traded Conversions | C286: nair@nexora.live | D286: 46226.436 | E286: =INT(D286) -> 46226 | F286: MAIN WEBSITE (HOT) | G286: =_xlfn.XLOOKUP(A286,FTD!A:A,FTD!C:C) -> 24000 | H286: {=_xlfn.LET( _xlpm.s, TRIM(F286), _xlpm.p, _xlfn.LAMBDA(_xlpm.x, LEFT(_xlpm.s, LEN(_xlpm.x)) = _xlpm.x), _xlfn.IFS( _xlpm.p("meta6"), 1, _xlpm.p("meta"), 3, _xlpm.p("ref"), 3, OR(_xlpm.p("telegram"), _xlpm.p("instagram"), _xlpm.p("stock meme"), _xlpm.p("gx")), 2, OR(_xlpm.p("application"), _xlpm.p("main website"), _xlpm.p("direct (hot)"), _xlpm.p("sunil"), _xlpm.p("prs"), _xlpm.p("invst (hot)")), 1, TRUE, 2 ) )} -> 1 | I286: =_xlfn.XLOOKUP(E286,Calendar!C:C,Calendar!B:B) -> Working Day | M286: 46217 | N286: deepa.negi@nexora.live | O286: Working Day | P286: 4 | Q286: =_xlfn.XLOOKUP(N286,Attendance!F:F,Attendance!J:J) -> Meta | R286: =_xlfn.LET( _xlpm.pool, IFERROR(Q286&"", ""), _xlpm.conv, IFERROR(--P286, 0), _xlpm.mkt, O287="Working Day", IF(_xlpm.pool="1", IF(_xlpm.mkt, IF(_xlpm.conv>=12,700,IF(_xlpm.conv>=8,300,0)), IF(_xlpm.conv>=7,700,IF(_xlpm.conv>=4,300,0))), IF(_xlpm.pool="Meta", IF(_xlpm.mkt, IF(_xlpm.conv>=6,700,IF(_xlpm.conv>=4,400,0)), IF(_xlpm.conv>=4,700,IF(_xlpm.conv>=3,400,0))), IF(_xlpm.mkt, IF(_xlpm.conv>=5,700,IF(_xlpm.conv>=3,500,0)), IF(_xlpm.conv>=3,700,IF(_xlpm.conv>=2,500,0))) ))) -> 400
A287: M148023 | B287: Traded Conversions | C287: shubham.a@nexora.live | D287: 46223.507 | E287: =INT(D287) -> 46223 | F287: Referral (HOT) | G287: =_xlfn.XLOOKUP(A287,FTD!A:A,FTD!C:C) -> 1000 | H287: {=_xlfn.LET( _xlpm.s, TRIM(F287), _xlpm.p, _xlfn.LAMBDA(_xlpm.x, LEFT(_xlpm.s, LEN(_xlpm.x)) = _xlpm.x), _xlfn.IFS( _xlpm.p("meta6"), 1, _xlpm.p("meta"), 3, _xlpm.p("ref"), 3, OR(_xlpm.p("telegram"), _xlpm.p("instagram"), _xlpm.p("stock meme"), _xlpm.p("gx")), 2, OR(_xlpm.p("application"), _xlpm.p("main website"), _xlpm.p("direct (hot)"), _xlpm.p("sunil"), _xlpm.p("prs"), _xlpm.p("invst (hot)")), 1, TRUE, 2 ) )} -> 3 | I287: =_xlfn.XLOOKUP(E287,Calendar!C:C,Calendar!B:B) -> Working Day | M287: 46217 | N287: deepraj@nexora.live | O287: Working Day | P287: 1 | Q287: =_xlfn.XLOOKUP(N287,Attendance!F:F,Attendance!J:J) -> New OJT | R287: =_xlfn.LET( _xlpm.pool, IFERROR(Q287&"", ""), _xlpm.conv, IFERROR(--P287, 0), _xlpm.mkt, O288="Working Day", IF(_xlpm.pool="1", IF(_xlpm.mkt, IF(_xlpm.conv>=12,700,IF(_xlpm.conv>=8,300,0)), IF(_xlpm.conv>=7,700,IF(_xlpm.conv>=4,300,0))), IF(_xlpm.pool="Meta", IF(_xlpm.mkt, IF(_xlpm.conv>=6,700,IF(_xlpm.conv>=4,400,0)), IF(_xlpm.conv>=4,700,IF(_xlpm.conv>=3,400,0))), IF(_xlpm.mkt, IF(_xlpm.conv>=5,700,IF(_xlpm.conv>=3,500,0)), IF(_xlpm.conv>=3,700,IF(_xlpm.conv>=2,500,0))) ))) -> 0
A288: P139422 | B288: Traded Conversions | C288: ankita@nexora.live | D288: 46209.551 | E288: =INT(D288) -> 46209 | F288: Meta6 | G288: =_xlfn.XLOOKUP(A288,FTD!A:A,FTD!C:C) -> 2000 | H288: {=_xlfn.LET( _xlpm.s, TRIM(F288), _xlpm.p, _xlfn.LAMBDA(_xlpm.x, LEFT(_xlpm.s, LEN(_xlpm.x)) = _xlpm.x), _xlfn.IFS( _xlpm.p("meta6"), 1, _xlpm.p("meta"), 3, _xlpm.p("ref"), 3, OR(_xlpm.p("telegram"), _xlpm.p("instagram"), _xlpm.p("stock meme"), _xlpm.p("gx")), 2, OR(_xlpm.p("application"), _xlpm.p("main website"), _xlpm.p("direct (hot)"), _xlpm.p("sunil"), _xlpm.p("prs"), _xlpm.p("invst (hot)")), 1, TRUE, 2 ) )} -> 1 | I288: =_xlfn.XLOOKUP(E288,Calendar!C:C,Calendar!B:B) -> Working Day | M288: 46217 | N288: divya.d@nexora.live | O288: Working Day | P288: 1 | Q288: =_xlfn.XLOOKUP(N288,Attendance!F:F,Attendance!J:J) -> New OJT | R288: =_xlfn.LET( _xlpm.pool, IFERROR(Q288&"", ""), _xlpm.conv, IFERROR(--P288, 0), _xlpm.mkt, O289="Working Day", IF(_xlpm.pool="1", IF(_xlpm.mkt, IF(_xlpm.conv>=12,700,IF(_xlpm.conv>=8,300,0)), IF(_xlpm.conv>=7,700,IF(_xlpm.conv>=4,300,0))), IF(_xlpm.pool="Meta", IF(_xlpm.mkt, IF(_xlpm.conv>=6,700,IF(_xlpm.conv>=4,400,0)), IF(_xlpm.conv>=4,700,IF(_xlpm.conv>=3,400,0))), IF(_xlpm.mkt, IF(_xlpm.conv>=5,700,IF(_xlpm.conv>=3,500,0)), IF(_xlpm.conv>=3,700,IF(_xlpm.conv>=2,500,0))) ))) -> 0
A289: P110973 | B289: Traded Conversions | C289: aamir@nexora.live | D289: 46218.906 | E289: =INT(D289) -> 46218 | F289: META6 | G289: =_xlfn.XLOOKUP(A289,FTD!A:A,FTD!C:C) -> 1000 | H289: {=_xlfn.LET( _xlpm.s, TRIM(F289), _xlpm.p, _xlfn.LAMBDA(_xlpm.x, LEFT(_xlpm.s, LEN(_xlpm.x)) = _xlpm.x), _xlfn.IFS( _xlpm.p("meta6"), 1, _xlpm.p("meta"), 3, _xlpm.p("ref"), 3, OR(_xlpm.p("telegram"), _xlpm.p("instagram"), _xlpm.p("stock meme"), _xlpm.p("gx")), 2, OR(_xlpm.p("application"), _xlpm.p("main website"), _xlpm.p("direct (hot)"), _xlpm.p("sunil"), _xlpm.p("prs"), _xlpm.p("invst (hot)")), 1, TRUE, 2 ) )} -> 1 | I289: =_xlfn.XLOOKUP(E289,Calendar!C:C,Calendar!B:B) -> Working Day | M289: 46217 | N289: fahrukh@nexora.live | O289: Working Day | P289: 1 | Q289: =_xlfn.XLOOKUP(N289,Attendance!F:F,Attendance!J:J) -> Meta | R289: =_xlfn.LET( _xlpm.pool, IFERROR(Q289&"", ""), _xlpm.conv, IFERROR(--P289, 0), _xlpm.mkt, O290="Working Day", IF(_xlpm.pool="1", IF(_xlpm.mkt, IF(_xlpm.conv>=12,700,IF(_xlpm.conv>=8,300,0)), IF(_xlpm.conv>=7,700,IF(_xlpm.conv>=4,300,0))), IF(_xlpm.pool="Meta", IF(_xlpm.mkt, IF(_xlpm.conv>=6,700,IF(_xlpm.conv>=4,400,0)), IF(_xlpm.conv>=4,700,IF(_xlpm.conv>=3,400,0))), IF(_xlpm.mkt, IF(_xlpm.conv>=5,700,IF(_xlpm.conv>=3,500,0)), IF(_xlpm.conv>=3,700,IF(_xlpm.conv>=2,500,0))) ))) -> 0
A290: V146262 | B290: Traded Conversions | C290: divya.d@nexora.live | D290: 46218.829 | E290: =INT(D290) -> 46218 | F290: Referral (HOT) | G290: =_xlfn.XLOOKUP(A290,FTD!A:A,FTD!C:C) -> 1200 | H290: {=_xlfn.LET( _xlpm.s, TRIM(F290), _xlpm.p, _xlfn.LAMBDA(_xlpm.x, LEFT(_xlpm.s, LEN(_xlpm.x)) = _xlpm.x), _xlfn.IFS( _xlpm.p("meta6"), 1, _xlpm.p("meta"), 3, _xlpm.p("ref"), 3, OR(_xlpm.p("telegram"), _xlpm.p("instagram"), _xlpm.p("stock meme"), _xlpm.p("gx")), 2, OR(_xlpm.p("application"), _xlpm.p("main website"), _xlpm.p("direct (hot)"), _xlpm.p("sunil"), _xlpm.p("prs"), _xlpm.p("invst (hot)")), 1, TRUE, 2 ) )} -> 3 | I290: =_xlfn.XLOOKUP(E290,Calendar!C:C,Calendar!B:B) -> Working Day | M290: 46217 | N290: haresh@nexora.live | O290: Working Day | P290: 1 | Q290: =_xlfn.XLOOKUP(N290,Attendance!F:F,Attendance!J:J) -> Meta | R290: =_xlfn.LET( _xlpm.pool, IFERROR(Q290&"", ""), _xlpm.conv, IFERROR(--P290, 0), _xlpm.mkt, O291="Working Day", IF(_xlpm.pool="1", IF(_xlpm.mkt, IF(_xlpm.conv>=12,700,IF(_xlpm.conv>=8,300,0)), IF(_xlpm.conv>=7,700,IF(_xlpm.conv>=4,300,0))), IF(_xlpm.pool="Meta", IF(_xlpm.mkt, IF(_xlpm.conv>=6,700,IF(_xlpm.conv>=4,400,0)), IF(_xlpm.conv>=4,700,IF(_xlpm.conv>=3,400,0))), IF(_xlpm.mkt, IF(_xlpm.conv>=5,700,IF(_xlpm.conv>=3,500,0)), IF(_xlpm.conv>=3,700,IF(_xlpm.conv>=2,500,0))) ))) -> 0
A291: A145679 | B291: Traded Conversions | C291: waman@nexora.live | D291: 46217.444 | E291: =INT(D291) -> 46217 | F291: MAIN WEBSITE (HOT) | G291: =_xlfn.XLOOKUP(A291,FTD!A:A,FTD!C:C) -> 1000 | H291: {=_xlfn.LET( _xlpm.s, TRIM(F291), _xlpm.p, _xlfn.LAMBDA(_xlpm.x, LEFT(_xlpm.s, LEN(_xlpm.x)) = _xlpm.x), _xlfn.IFS( _xlpm.p("meta6"), 1, _xlpm.p("meta"), 3, _xlpm.p("ref"), 3, OR(_xlpm.p("telegram"), _xlpm.p("instagram"), _xlpm.p("stock meme"), _xlpm.p("gx")), 2, OR(_xlpm.p("application"), _xlpm.p("main website"), _xlpm.p("direct (hot)"), _xlpm.p("sunil"), _xlpm.p("prs"), _xlpm.p("invst (hot)")), 1, TRUE, 2 ) )} -> 1 | I291: =_xlfn.XLOOKUP(E291,Calendar!C:C,Calendar!B:B) -> Working Day | M291: 46217 | N291: irfan@nexora.live | O291: Working Day | P291: 2 | Q291: =_xlfn.XLOOKUP(N291,Attendance!F:F,Attendance!J:J) -> Meta | R291: =_xlfn.LET( _xlpm.pool, IFERROR(Q291&"", ""), _xlpm.conv, IFERROR(--P291, 0), _xlpm.mkt, O292="Working Day", IF(_xlpm.pool="1", IF(_xlpm.mkt, IF(_xlpm.conv>=12,700,IF(_xlpm.conv>=8,300,0)), IF(_xlpm.conv>=7,700,IF(_xlpm.conv>=4,300,0))), IF(_xlpm.pool="Meta", IF(_xlpm.mkt, IF(_xlpm.conv>=6,700,IF(_xlpm.conv>=4,400,0)), IF(_xlpm.conv>=4,700,IF(_xlpm.conv>=3,400,0))), IF(_xlpm.mkt, IF(_xlpm.conv>=5,700,IF(_xlpm.conv>=3,500,0)), IF(_xlpm.conv>=3,700,IF(_xlpm.conv>=2,500,0))) ))) -> 0
A292: B142642 | B292: Traded Conversions | C292: waman@nexora.live | D292: 46216.938 | E292: =INT(D292) -> 46216 | F292: Referral (HOT) | G292: =_xlfn.XLOOKUP(A292,FTD!A:A,FTD!C:C) -> 6000 | H292: {=_xlfn.LET( _xlpm.s, TRIM(F292), _xlpm.p, _xlfn.LAMBDA(_xlpm.x, LEFT(_xlpm.s, LEN(_xlpm.x)) = _xlpm.x), _xlfn.IFS( _xlpm.p("meta6"), 1, _xlpm.p("meta"), 3, _xlpm.p("ref"), 3, OR(_xlpm.p("telegram"), _xlpm.p("instagram"), _xlpm.p("stock meme"), _xlpm.p("gx")), 2, OR(_xlpm.p("application"), _xlpm.p("main website"), _xlpm.p("direct (hot)"), _xlpm.p("sunil"), _xlpm.p("prs"), _xlpm.p("invst (hot)")), 1, TRUE, 2 ) )} -> 3 | I292: =_xlfn.XLOOKUP(E292,Calendar!C:C,Calendar!B:B) -> Working Day | M292: 46217 | N292: kawaljit.k@nexora.live | O292: Working Day | P292: 3 | Q292: =_xlfn.XLOOKUP(N292,Attendance!F:F,Attendance!J:J) -> Meta | R292: =_xlfn.LET( _xlpm.pool, IFERROR(Q292&"", ""), _xlpm.conv, IFERROR(--P292, 0), _xlpm.mkt, O293="Working Day", IF(_xlpm.pool="1", IF(_xlpm.mkt, IF(_xlpm.conv>=12,700,IF(_xlpm.conv>=8,300,0)), IF(_xlpm.conv>=7,700,IF(_xlpm.conv>=4,300,0))), IF(_xlpm.pool="Meta", IF(_xlpm.mkt, IF(_xlpm.conv>=6,700,IF(_xlpm.conv>=4,400,0)), IF(_xlpm.conv>=4,700,IF(_xlpm.conv>=3,400,0))), IF(_xlpm.mkt, IF(_xlpm.conv>=5,700,IF(_xlpm.conv>=3,500,0)), IF(_xlpm.conv>=3,700,IF(_xlpm.conv>=2,500,0))) ))) -> 0
A293: K145716 | B293: Traded Conversions | C293: abhishek.k@nexora.live | D293: 46217.558 | E293: =INT(D293) -> 46217 | F293: Telegram ads | G293: =_xlfn.XLOOKUP(A293,FTD!A:A,FTD!C:C) -> 1000 | H293: {=_xlfn.LET( _xlpm.s, TRIM(F293), _xlpm.p, _xlfn.LAMBDA(_xlpm.x, LEFT(_xlpm.s, LEN(_xlpm.x)) = _xlpm.x), _xlfn.IFS( _xlpm.p("meta6"), 1, _xlpm.p("meta"), 3, _xlpm.p("ref"), 3, OR(_xlpm.p("telegram"), _xlpm.p("instagram"), _xlpm.p("stock meme"), _xlpm.p("gx")), 2, OR(_xlpm.p("application"), _xlpm.p("main website"), _xlpm.p("direct (hot)"), _xlpm.p("sunil"), _xlpm.p("prs"), _xlpm.p("invst (hot)")), 1, TRUE, 2 ) )} -> 2 | I293: =_xlfn.XLOOKUP(E293,Calendar!C:C,Calendar!B:B) -> Working Day | M293: 46217 | N293: mitali@nexora.live | O293: Working Day | P293: 2 | Q293: =_xlfn.XLOOKUP(N293,Attendance!F:F,Attendance!J:J) -> Telegram | R293: =_xlfn.LET( _xlpm.pool, IFERROR(Q293&"", ""), _xlpm.conv, IFERROR(--P293, 0), _xlpm.mkt, O294="Working Day", IF(_xlpm.pool="1", IF(_xlpm.mkt, IF(_xlpm.conv>=12,700,IF(_xlpm.conv>=8,300,0)), IF(_xlpm.conv>=7,700,IF(_xlpm.conv>=4,300,0))), IF(_xlpm.pool="Meta", IF(_xlpm.mkt, IF(_xlpm.conv>=6,700,IF(_xlpm.conv>=4,400,0)), IF(_xlpm.conv>=4,700,IF(_xlpm.conv>=3,400,0))), IF(_xlpm.mkt, IF(_xlpm.conv>=5,700,IF(_xlpm.conv>=3,500,0)), IF(_xlpm.conv>=3,700,IF(_xlpm.conv>=2,500,0))) ))) -> 0
A294: K139447 | B294: Traded Conversions | C294: shambu@nexora.live | D294: 46210.582 | E294: =INT(D294) -> 46210 | F294: Meta6 | G294: =_xlfn.XLOOKUP(A294,FTD!A:A,FTD!C:C) -> 1000 | H294: {=_xlfn.LET( _xlpm.s, TRIM(F294), _xlpm.p, _xlfn.LAMBDA(_xlpm.x, LEFT(_xlpm.s, LEN(_xlpm.x)) = _xlpm.x), _xlfn.IFS( _xlpm.p("meta6"), 1, _xlpm.p("meta"), 3, _xlpm.p("ref"), 3, OR(_xlpm.p("telegram"), _xlpm.p("instagram"), _xlpm.p("stock meme"), _xlpm.p("gx")), 2, OR(_xlpm.p("application"), _xlpm.p("main website"), _xlpm.p("direct (hot)"), _xlpm.p("sunil"), _xlpm.p("prs"), _xlpm.p("invst (hot)")), 1, TRUE, 2 ) )} -> 1 | I294: =_xlfn.XLOOKUP(E294,Calendar!C:C,Calendar!B:B) -> Working Day | M294: 46217 | N294: monika@nexora.live | O294: Working Day | P294: 2 | Q294: =_xlfn.XLOOKUP(N294,Attendance!F:F,Attendance!J:J) -> #N/A | R294: =_xlfn.LET( _xlpm.pool, IFERROR(Q294&"", ""), _xlpm.conv, IFERROR(--P294, 0), _xlpm.mkt, O295="Working Day", IF(_xlpm.pool="1", IF(_xlpm.mkt, IF(_xlpm.conv>=12,700,IF(_xlpm.conv>=8,300,0)), IF(_xlpm.conv>=7,700,IF(_xlpm.conv>=4,300,0))), IF(_xlpm.pool="Meta", IF(_xlpm.mkt, IF(_xlpm.conv>=6,700,IF(_xlpm.conv>=4,400,0)), IF(_xlpm.conv>=4,700,IF(_xlpm.conv>=3,400,0))), IF(_xlpm.mkt, IF(_xlpm.conv>=5,700,IF(_xlpm.conv>=3,500,0)), IF(_xlpm.conv>=3,700,IF(_xlpm.conv>=2,500,0))) ))) -> 0
...

Sheet Calendar
A1: calendar_date | B1: Status | C1: Date Clean
A2: 46023 | B2: =_xlfn.LET(_xlpm.x, _xlfn.XLOOKUP(A2,Holidays!A:A,Holidays!B:B,""), IF(_xlpm.x="", "Working Day", _xlpm.x)) -> Working Day | C2: =INT(A2) -> 46023
A3: 46024 | B3: =_xlfn.LET(_xlpm.x, _xlfn.XLOOKUP(A3,Holidays!A:A,Holidays!B:B,""), IF(_xlpm.x="", "Working Day", _xlpm.x)) -> Working Day | C3: =INT(A3) -> 46024
A4: 46025 | B4: =_xlfn.LET(_xlpm.x, _xlfn.XLOOKUP(A4,Holidays!A:A,Holidays!B:B,""), IF(_xlpm.x="", "Working Day", _xlpm.x)) -> Saturday | C4: =INT(A4) -> 46025
A5: 46026 | B5: =_xlfn.LET(_xlpm.x, _xlfn.XLOOKUP(A5,Holidays!A:A,Holidays!B:B,""), IF(_xlpm.x="", "Working Day", _xlpm.x)) -> Sunday | C5: =INT(A5) -> 46026
A6: 46027 | B6: =_xlfn.LET(_xlpm.x, _xlfn.XLOOKUP(A6,Holidays!A:A,Holidays!B:B,""), IF(_xlpm.x="", "Working Day", _xlpm.x)) -> Working Day | C6: =INT(A6) -> 46027
A7: 46028 | B7: =_xlfn.LET(_xlpm.x, _xlfn.XLOOKUP(A7,Holidays!A:A,Holidays!B:B,""), IF(_xlpm.x="", "Working Day", _xlpm.x)) -> Working Day | C7: =INT(A7) -> 46028
A8: 46029 | B8: =_xlfn.LET(_xlpm.x, _xlfn.XLOOKUP(A8,Holidays!A:A,Holidays!B:B,""), IF(_xlpm.x="", "Working Day", _xlpm.x)) -> Working Day | C8: =INT(A8) -> 46029
A9: 46030 | B9: =_xlfn.LET(_xlpm.x, _xlfn.XLOOKUP(A9,Holidays!A:A,Holidays!B:B,""), IF(_xlpm.x="", "Working Day", _xlpm.x)) -> Working Day | C9: =INT(A9) -> 46030
A10: 46031 | B10: =_xlfn.LET(_xlpm.x, _xlfn.XLOOKUP(A10,Holidays!A:A,Holidays!B:B,""), IF(_xlpm.x="", "Working Day", _xlpm.x)) -> Working Day | C10: =INT(A10) -> 46031
A11: 46032 | B11: =_xlfn.LET(_xlpm.x, _xlfn.XLOOKUP(A11,Holidays!A:A,Holidays!B:B,""), IF(_xlpm.x="", "Working Day", _xlpm.x)) -> Saturday | C11: =INT(A11) -> 46032
A12: 46033 | B12: =_xlfn.LET(_xlpm.x, _xlfn.XLOOKUP(A12,Holidays!A:A,Holidays!B:B,""), IF(_xlpm.x="", "Working Day", _xlpm.x)) -> Sunday | C12: =INT(A12) -> 46033
A13: 46034 | B13: =_xlfn.LET(_xlpm.x, _xlfn.XLOOKUP(A13,Holidays!A:A,Holidays!B:B,""), IF(_xlpm.x="", "Working Day", _xlpm.x)) -> Working Day | C13: =INT(A13) -> 46034
... A366: 46387 | B366: =_xlfn.LET(_xlpm.x, _xlfn.XLOOKUP(A366,Holidays!A:A,Holidays!B:B,""), IF(_xlpm.x="", "Working Day", _xlpm.x)) -> Working Day | C366: =INT(A366) -> 46387

Sheet Holidays
A1: Date | B1: Holiday_Type
A2: 46025 | B2: Saturday
A3: 46026 | B3: Sunday
A4: 46032 | B4: Saturday
A5: 46033 | B5: Sunday
A6: 46039 | B6: Saturday
A7: 46040 | B7: Sunday
A8: 46046 | B8: Saturday
A9: 46047 | B9: Sunday
A10: 46048 | B10: NSE Holiday
A11: 46053 | B11: Saturday
A12: 46054 | B12: Sunday
A13: 46060 | B13: Saturday
... A120: 46383 | B120: Sunday

Sheet FTD
A1: l.ClientID | B1: fd.first_day | C1: first_day_deposit
A2: Y45610 | B2: 46003 | C2: 500
A3: M29365 | B3: 46006 | C3: 500
A4: M48679 | B4: 46008 | C4: 500
A5: P54093 | B5: 46017 | C5: 500
A6: P61669 | B6: 46037 | C6: 1000
A7: V57067 | B7: 46056 | C7: 1001
A8: B74568 | B8: 46057 | C8: 1000
A9: P76843 | B9: 46059 | C9: 1000
A10: R68577 | B10: 46078 | C10: 2500
A11: R89787 | B11: 46087 | C11: 527
A12: V63623 | B12: 46100 | C12: 1000
A13: S98681 | B13: 46106 | C13: 1000
... A1381: S150553 | B1381: 46234 | C1381: 1000

Sheet Attendance
A1: SR No | B1: Employee code | C1: CRM ID | D1: CRM Name | E1: Full Name | F1: Email ID | G1: Religion | H1: Date Of Joining | I1: Shift | J1: Pool | K1: TL | L1: Location | M1: Status - Active/Inactive | N1: Scalebot | O1: Whatsapp | P1: Whatsapp Number | Q1: Watii | R1: Virtual Whatsapp | S1: Language | T1: New web trader account id | U1: 46204 | V1: 46205 | W1: 46206 | X1: 46207 | Y1: 46208 | Z1: 46209 | AA1: 46210 | AB1: 46211 | AC1: 46212 | AD1: 46213 | AE1: 46214 | AF1: 46215 | AG1: 46216 | AH1: 46217 | AI1: 46218 | AJ1: 46219 | AK1: 46220 | AL1: 46221 | AM1: 46222 | AN1: 46223 | AO1: 46224 | AP1: 46225 | AQ1: 46226 | AR1: 46227 | AS1: 46228 | AT1: 46229 | AU1: 46230 | AV1: 46231 | AW1: 46232 | AX1: 46233 | AY1: 46234 | AZ1: Total Days | BA1: Present | BB1: Half-Day | BC1: Leave | BD1: Casual leave | BE1: Holiday | BF1: Comp-off | BG1: Earned Leave | BH1: UL/Leave | BI1: UL P | BJ1: LWP/Penalty | BK1: Week Off | BL1: Payable Days | BM1: Final Target | BN1: Refer Target | BO1: Incentive Eligibility | BP1: Refer Eligibility | BQ1: Leaves
A2: 1 | B2: E-1253 | C2: 13INASHUTOSH0823 | D2: Ashutosh | E2: Ashutosh Singh | F2: ashutosh@nexora.live | G2: NON MUSLIM | H2: 45152 | J2: 1 | K2: Saif | L2: WFH - Adya IT | M2: Active | N2: No | O2: No | P2: 9301953889 | R2: +1 (938) 290-0306 | S2: Hindi,English | T2: A18844 | U2: PP | V2: Leave | W2: PP | X2: WO | Y2: PP | Z2: PP | AA2: PP | AB2: PP | AC2: PP | AD2: PP | AE2: PP | AF2: WO | AG2: PP | AH2: PP | AI2: PP | AJ2: PP | AK2: PP | AL2: WO | AM2: PP | AN2: PP | AO2: PP | AP2: PP | AQ2: PP | AR2: PP | AS2: WO | AT2: PP | AU2: PP | AV2: PP | AW2: PP | AX2: PP | AZ2: =COUNTA(U2:AY2)-COUNTIF(U2:AY2,"N/A")-COUNTIF(U2:AY2,"attrite") -> 30 | BA2: =COUNTIF(U2:AY2,"PP") -> 25 | BB2: =COUNTIF(U2:AY2,"Half-Day") -> 0 | BC2: =COUNTIF(U2:AY2,"Leave") -> 1 | BD2: =COUNTIF(U2:AY2,"CL") -> 0 | BE2: =COUNTIF(U2:AY2,"HO") -> 0 | BF2: =COUNTIF(AY2:$BZT2,"Comp-off") -> 0 | BG2: =COUNTIF(U2:AY2,"EL") -> 0 | BH2: =COUNTIF(U2:AY2,"UL") -> 0 | BI2: =COUNTIF(U2:AY2,"UL P") -> 0 | BJ2: =COUNTIF(U2:AY2,"LWP") -> 0 | BK2: =COUNTIF(U2:AY2,"WO") -> 4 | BL2: =BA2+BB2*0.5+BK2+BE2+BD2+BF2+BG2 -> 29 | BM2: 120 | BN2: 25 | BO2: =INT(BM2*0.8) -> 96 | BP2: =INT(BN2*0.8) -> 20 | BQ2: =BB2*0.5+BC2+BH2 -> 1
A3: 2 | B3: E-1255 | C3: 18INPRINCE0923 | D3: Prince Priye | E3: Prince Priye | F3: prince@nexora.live | G3: NON MUSLIM | H3: 45182 | J3: 1 | K3: Saif | L3: WFH - Adya IT | M3: Active | N3: No | O3: No | P3: 9589543480 | R3: +44 7781587534 | S3: Hindi and English | T3: P18858 | U3: Leave | V3: UL | W3: PP | X3: PP | Y3: WO | Z3: PP | AA3: PP | AB3: PP | AC3: PP | AD3: PP | AE3: WO | AF3: PP | AG3: PP | AH3: PP | AI3: PP | AJ3: PP | AK3: PP | AL3: PP | AM3: WO | AN3: PP | AO3: PP | AP3: PP | AQ3: PP | AR3: PP | AS3: CL | AT3: WO | AU3: PP | AV3: PP | AW3: PP | AX3: PP | AZ3: =COUNTA(U3:AY3)-COUNTIF(U3:AY3,"N/A")-COUNTIF(U3:AY3,"attrite") -> 30 | BA3: =COUNTIF(U3:AY3,"PP") -> 23 | BB3: =COUNTIF(U3:AY3,"Half-Day") -> 0 | BC3: =COUNTIF(U3:AY3,"Leave") -> 1 | BD3: =COUNTIF(U3:AY3,"CL") -> 1 | BE3: =COUNTIF(U3:AY3,"HO") -> 0 | BF3: =COUNTIF(AY3:$BZT3,"Comp-off") -> 0 | BG3: =COUNTIF(U3:AY3,"EL") -> 0 | BH3: =COUNTIF(U3:AY3,"UL") -> 1 | BI3: =COUNTIF(U3:AY3,"UL P") -> 0 | BJ3: =COUNTIF(U3:AY3,"LWP") -> 0 | BK3: =COUNTIF(U3:AY3,"WO") -> 4 | BL3: =BA3+BB3*0.5+BK3+BE3+BD3+BF3+BG3 -> 28 | BM3: 120 | BN3: 25 | BO3: =INT(BM3*0.8) -> 96 | BP3: =INT(BN3*0.8) -> 20 | BQ3: =BB3*0.5+BC3+BH3 -> 2
A4: 3 | B4: E-1252 | C4: 88WAMAN1123 | D4: Waman A | E4: Waman Avhad | F4: waman@nexora.live | G4: NON MUSLIM | H4: 45512 | J4: 1 | K4: Saif | L4: WFH - Adya IT | M4: Active | N4: Yes | O4: No | P4: 7415290527 | R4: No | S4: Marathi and Hindi | T4: W18916 | U4: PP | V4: PP | W4: PP | X4: Leave | Y4: WO | Z4: PP | AA4: PP | AB4: PP | AC4: PP | AD4: PP | AE4: WO | AF4: PP | AG4: PP | AH4: PP | AI4: PP | AJ4: PP | AK4: Leave | AL4: PP | AM4: WO | AN4: PP | AO4: PP | AP4: PP | AQ4: PP | AR4: PP | AS4: WO | AT4: PP | AU4: PP | AV4: PP | AW4: PP | AX4: PP | AZ4: =COUNTA(U4:AY4)-COUNTIF(U4:AY4,"N/A")-COUNTIF(U4:AY4,"attrite") -> 30 | BA4: =COUNTIF(U4:AY4,"PP") -> 24 | BB4: =COUNTIF(U4:AY4,"Half-Day") -> 0 | BC4: =COUNTIF(U4:AY4,"Leave") -> 2 | BD4: =COUNTIF(U4:AY4,"CL") -> 0 | BE4: =COUNTIF(U4:AY4,"HO") -> 0 | BF4: =COUNTIF(AY4:$BZT4,"Comp-off") -> 0 | BG4: =COUNTIF(U4:AY4,"EL") -> 0 | BH4: =COUNTIF(U4:AY4,"UL") -> 0 | BI4: =COUNTIF(U4:AY4,"UL P") -> 0 | BJ4: =COUNTIF(U4:AY4,"LWP") -> 0 | BK4: =COUNTIF(U4:AY4,"WO") -> 4 | BL4: =BA4+BB4*0.5+BK4+BE4+BD4+BF4+BG4 -> 28 | BM4: 120 | BN4: 25 | BO4: =INT(BM4*0.8) -> 96 | BP4: =INT(BN4*0.8) -> 20 | BQ4: =BB4*0.5+BC4+BH4 -> 2
A5: 4 | B5: E-1706 | C5: 520INNair0525 | D5: Nair | E5: Narendra Merotra | F5: nair@nexora.live | G5: NON MUSLIM | H5: 45800 | J5: 1 | K5: Saif | L5: WFH - Direct | M5: Active | N5: Yes | O5: No | P5: 9401001984 | R5: +1 2626125828 | S5: Hindi and English | T5: N72518 | U5: PP | V5: PP | W5: PP | X5: WO | Y5: PP | Z5: PP | AA5: PP | AB5: PP | AC5: PP | AD5: PP | AE5: PP | AF5: WO | AG5: Leave | AH5: Leave | AI5: PP | AJ5: PP | AK5: PP | AL5: WO | AM5: PP | AN5: PP | AO5: PP | AP5: PP | AQ5: PP | AR5: PP | AS5: PP | AT5: WO | AU5: PP | AV5: PP | AW5: PP | AX5: PP | AZ5: =COUNTA(U5:AY5)-COUNTIF(U5:AY5,"N/A")-COUNTIF(U5:AY5,"attrite") -> 30 | BA5: =COUNTIF(U5:AY5,"PP") -> 24 | BB5: =COUNTIF(U5:AY5,"Half-Day") -> 0 | BC5: =COUNTIF(U5:AY5,"Leave") -> 2 | BD5: =COUNTIF(U5:AY5,"CL") -> 0 | BE5: =COUNTIF(U5:AY5,"HO") -> 0 | BF5: =COUNTIF(AY5:$BZT5,"Comp-off") -> 0 | BG5: =COUNTIF(U5:AY5,"EL") -> 0 | BH5: =COUNTIF(U5:AY5,"UL") -> 0 | BI5: =COUNTIF(U5:AY5,"UL P") -> 0 | BJ5: =COUNTIF(U5:AY5,"LWP") -> 0 | BK5: =COUNTIF(U5:AY5,"WO") -> 4 | BL5: =BA5+BB5*0.5+BK5+BE5+BD5+BF5+BG5 -> 28 | BM5: 120 | BN5: 25 | BO5: =INT(BM5*0.8) -> 96 | BP5: =INT(BN5*0.8) -> 20 | BQ5: =BB5*0.5+BC5+BH5 -> 2
